Workbook

Sheet Параметры
B1: Параметры сезона 2027 — меняйте только жёлтые ячейки
B3: Параметр | C3: Значение | D3: Комментарий / источник
B4: Индексация цен 2027 к 2026 (по умолчанию для всех пакетов) | C4: 0.1 | D4: Допущение, не факт: ориентир ≈ инфляция + рост спроса. Замените на утверждённое значение. Для отдельного пакета индекс меняется в колонке «Индекс» матрицы.
B5: Шаг округления цены, ₽ | C5: 5000 | D5: Цены 2027 округляются до этого шага.
B6: Ранняя оплата: скидка (до 1 марта 2027) | C6: 0.05 | D6: Предложение механики early bird. Не применяется в матрице автоматически — используется в оферте.
B7: Стандартная предоплата по оферте | C7: 0.5 | D7: Доля цены пакета при акцепте оферты; остаток — до даты, указанной в оферте.
B8: Revenue share: доля организатора по умолчанию | C8: 0.2 | D8: Ориентир для договора деления выручки с резидентом. Уточнить по фактическим чекам 2026.
B9: Бар ВИП: доля организатора по умолчанию | C9: 0.25 | D9: Ориентир для договора на торговлю напитками в ВИП.
B12: Легенда
B13: Синий шрифт на жёлтом | C13: ввод: меняйте
B14: Зелёный шрифт | C14: ссылка на этот лист
B15: Чёрный шрифт | C15: формула — не трогать
B16: Цены 2026 | C16: перенесены из файла-примера 2026 без изменений (данные пользователя)

Sheet Матрица 2027
B1: Матрица пакетов участия — Пикник Афиши 2027
B2: Цены 2026 — из файла 2026. Цены 2027 = цена 2026 × (1 + индекс), с округлением (лист «Параметры»). Вар.1 = железная застройка / основной вариант, вар.2 = деревянная / альтернативный (для «2 варианта» — уточнить, чем отличаются).
B4: Название пакета | C4: Площадка | D4: Вариант застройки / Тип | E4: Цена 2026, вар.1 (Ж) ₽ | F4: Цена 2026, вар.2 (Д) ₽ | G4: Ед. | H4: Индекс 2027 | I4: Цена 2027, вар.1 ₽ | J4: Цена 2027, вар.2 ₽ | K4: Предоплата | L4: Торг. точка (кв.м) | M4: Техн. зона (кв.м) | N4: Электричество (кВт) | O4: Аккредитация (чел.) | P4: Доп. билеты (шт.) | Q4: Включенные услуги | R4: Основной формат договора | S4: Альтернативный формат | T4: План продаж 2027, вар.1 (шт) | U4: План продаж 2027, вар.2 (шт) | V4: Выручка план 2027 ₽
B5: ПЛОЩАДКА №1 (Москва)
B6: Корнер №1 | C6: Москва | D6: Железная / Деревянная | E6: 195000 | F6: 160000 | G6: пакет | H6: =Параметры!$C$4 -> 0.1 | I6: =IF(E6="","",ROUND(E6*(1+$H6)/Параметры!$C$5,0)*Параметры!$C$5) -> 215000 | J6: =IF(F6="","",ROUND(F6*(1+$H6)/Параметры!$C$5,0)*Параметры!$C$5) -> 175000 | K6: 100% (3 дня) | L6: 9 | M6: 4 | N6: 2 | O6: 2 | P6: — | Q6: Брендирование, печать меню, вывоз мусора, разрешение | R6: Оферта | V6: =IF(N(I6)*N(T6)+N(J6)*N(U6)=0,"",N(I6)*N(T6)+N(J6)*N(U6))
B7: Корнер №2 | C7: Москва | D7: Железная / Деревянная | E7: 240000 | F7: 180000 | G7: пакет | H7: =Параметры!$C$4 -> 0.1 | I7: =IF(E7="","",ROUND(E7*(1+$H7)/Параметры!$C$5,0)*Параметры!$C$5) -> 265000 | J7: =IF(F7="","",ROUND(F7*(1+$H7)/Параметры!$C$5,0)*Параметры!$C$5) -> 200000 | K7: — | L7: 9 | M7: 4 | N7: 5 | O7: 5 | P7: — | Q7: Брендирование, печать меню, вывоз мусора, разрешение | R7: Оферта | V7: =IF(N(I7)*N(T7)+N(J7)*N(U7)=0,"",N(I7)*N(T7)+N(J7)*N(U7))
B8: Корнер №3 | C8: Москва | D8: Железная / Деревянная | E8: 260000 | F8: 200000 | G8: пакет | H8: =Параметры!$C$4 -> 0.1 | I8: =IF(E8="","",ROUND(E8*(1+$H8)/Параметры!$C$5,0)*Параметры!$C$5) -> 285000 | J8: =IF(F8="","",ROUND(F8*(1+$H8)/Параметры!$C$5,0)*Параметры!$C$5) -> 220000 | K8: — | L8: 9 | M8: 4 | N8: 10 | O8: до 10 | P8: 5 | Q8: Брендирование, печать меню, вывоз мусора, разрешение | R8: Оферта | S8: Деление выручки | V8: =IF(N(I8)*N(T8)+N(J8)*N(U8)=0,"",N(I8)*N(T8)+N(J8)*N(U8))
B9: Корнер №4 | C9: Москва | D9: Железная / Деревянная | E9: 280000 | F9: 220000 | G9: пакет | H9: =Параметры!$C$4 -> 0.1 | I9: =IF(E9="","",ROUND(E9*(1+$H9)/Параметры!$C$5,0)*Параметры!$C$5) -> 310000 | J9: =IF(F9="","",ROUND(F9*(1+$H9)/Параметры!$C$5,0)*Параметры!$C$5) -> 240000 | K9: — | L9: 9 | M9: 4 | N9: 15 | O9: до 15 | P9: 10 | Q9: Брендирование, печать меню, вывоз мусора, разрешение | R9: Оферта | S9: Деление выручки | V9: =IF(N(I9)*N(T9)+N(J9)*N(U9)=0,"",N(I9)*N(T9)+N(J9)*N(U9))
B10: ВИП-корнер | C10: Москва | D10: — | E10: 250000 | G10: пакет | H10: =Параметры!$C$4 -> 0.1 | I10: =IF(E10="","",ROUND(E10*(1+$H10)/Параметры!$C$5,0)*Параметры!$C$5) -> 275000 | J10: =IF(F10="","",ROUND(F10*(1+$H10)/Параметры!$C$5,0)*Параметры!$C$5) | K10: — | L10: 9 | M10: 4 | N10: 10 | O10: до 10 | P10: 7 | Q10: Брендирование, печать меню, вывоз мусора | R10: Оферта | S10: Договор бар ВИП | V10: =IF(N(I10)*N(T10)+N(J10)*N(U10)=0,"",N(I10)*N(T10)+N(J10)*N(U10))
B11: ПЛОЩАДКА №2 (Санкт-Петербург)
B12: Корнер №1 | C12: Санкт-Петербург | D12: Железная / Деревянная | E12: 180000 | F12: 160000 | G12: пакет | H12: =Параметры!$C$4 -> 0.1 | I12: =IF(E12="","",ROUND(E12*(1+$H12)/Параметры!$C$5,0)*Параметры!$C$5) -> 200000 | J12: =IF(F12="","",ROUND(F12*(1+$H12)/Параметры!$C$5,0)*Параметры!$C$5) -> 175000 | K12: 100% (3 дня) | L12: 9 | M12: 4 | N12: 2 | O12: 2 | P12: — | Q12: Брендирование, печать меню, вывоз мусора, разрешение | R12: Оферта | V12: =IF(N(I12)*N(T12)+N(J12)*N(U12)=0,"",N(I12)*N(T12)+N(J12)*N(U12))
B13: Корнер №2 | C13: Санкт-Петербург | D13: Железная / Деревянная | E13: 220000 | F13: 180000 | G13: пакет | H13: =Параметры!$C$4 -> 0.1 | I13: =IF(E13="","",ROUND(E13*(1+$H13)/Параметры!$C$5,0)*Параметры!$C$5) -> 240000 | J13: =IF(F13="","",ROUND(F13*(1+$H13)/Параметры!$C$5,0)*Параметры!$C$5) -> 200000 | K13: — | L13: 9 | M13: 4 | N13: 5 | O13: 5 | P13: — | Q13: Брендирование, печать меню, вывоз мусора, разрешение | R13: Оферта | V13: =IF(N(I13)*N(T13)+N(J13)*N(U13)=0,"",N(I13)*N(T13)+N(J13)*N(U13))
B14: Корнер №3 | C14: Санкт-Петербург | D14: Железная / Деревянная | E14: 240000 | F14: 200000 | G14: пакет | H14: =Параметры!$C$4 -> 0.1 | I14: =IF(E14="","",ROUND(E14*(1+$H14)/Параметры!$C$5,0)*Параметры!$C$5) -> 265000 | J14: =IF(F14="","",ROUND(F14*(1+$H14)/Параметры!$C$5,0)*Параметры!$C$5) -> 220000 | K14: — | L14: 9 | M14: 4 | N14: 10 | O14: до 10 | P14: 5 | Q14: Брендирование, печать меню, вывоз мусора, разрешение | R14: Оферта | S14: Деление выручки | V14: =IF(N(I14)*N(T14)+N(J14)*N(U14)=0,"",N(I14)*N(T14)+N(J14)*N(U14))
B15: Корнер №4 | C15: Санкт-Петербург | D15: Железная / Деревянная | E15: 260000 | F15: 220000 | G15: пакет | H15: =Параметры!$C$4 -> 0.1 | I15: =IF(E15="","",ROUND(E15*(1+$H15)/Параметры!$C$5,0)*Параметры!$C$5) -> 285000 | J15: =IF(F15="","",ROUND(F15*(1+$H15)/Параметры!$C$5,0)*Параметры!$C$5) -> 240000 | K15: — | L15: 9 | M15: 4 | N15: 15 | O15: до 15 | P15: 10 | Q15: Брендирование, печать меню, вывоз мусора, разрешение | R15: Оферта | S15: Деление выручки | V15: =IF(N(I15)*N(T15)+N(J15)*N(U15)=0,"",N(I15)*N(T15)+N(J15)*N(U15))
B16: Фудтрак | C16: Санкт-Петербург | D16: — | E16: 250000 | G16: пакет | H16: =Параметры!$C$4 -> 0.1 | I16: =IF(E16="","",ROUND(E16*(1+$H16)/Параметры!$C$5,0)*Параметры!$C$5) -> 275000 | J16: =IF(F16="","",ROUND(F16*(1+$H16)/Параметры!$C$5,0)*Параметры!$C$5) | K16: — | L16: 10 | M16: — | N16: 10 | O16: до 10 | P16: 5 | Q16: Вывоз мусора, разрешение | R16: Оферта | S16: Деление выручки | V16: =IF(N(I16)*N(T16)+N(J16)*N(U16)=0,"",N(I16)*N(T16)+N(J16)*N(U16))
B17: ВИП-корнер | C17: Санкт-Петербург | D17: — | E17: 230000 | G17: пакет | H17: =Параметры!$C$4 -> 0.1 | I17: =IF(E17="","",ROUND(E17*(1+$H17)/Параметры!$C$5,0)*Параметры!$C$5) -> 255000 | J17: =IF(F17="","",ROUND(F17*(1+$H17)/Параметры!$C$5,0)*Параметры!$C$5) | K17: — | L17: 9 | M17: 4 | N17: 10 | O17: до 10 | P17: 7 | Q17: Брендирование, печать меню, вывоз мусора | R17: Оферта | S17: Договор бар ВИП | V17: =IF(N(I17)*N(T17)+N(J17)*N(U17)=0,"",N(I17)*N(T17)+N(J17)*N(U17))
B18: КОМБОПАКЕТЫ (Москва + Санкт-Петербург)
B19: Корнер №1 | C19: Комбо (1+2) | D19: Ж+Ж / Д+Д | E19: 320000 | F19: 280000 | G19: пакет | H19: =Параметры!$C$4 -> 0.1 | I19: =IF(E19="","",ROUND(E19*(1+$H19)/Параметры!$C$5,0)*Параметры!$C$5) -> 350000 | J19: =IF(F19="","",ROUND(F19*(1+$H19)/Параметры!$C$5,0)*Параметры!$C$5) -> 310000 | K19: — | L19: 9 (на каждой) | M19: 4 (на каждой) | N19: 5 (суммарно) | O19: до 5 | P19: — | Q19: Брендирование, печать меню, вывоз мусора, разрешение | R19: Оферта | V19: =IF(N(I19)*N(T19)+N(J19)*N(U19)=0,"",N(I19)*N(T19)+N(J19)*N(U19))
B20: Корнер №2 | C20: Комбо (1+2) | D20: Ж+Ж / Д+Д | E20: 340000 | F20: 300000 | G20: пакет | H20: =Параметры!$C$4 -> 0.1 | I20: =IF(E20="","",ROUND(E20*(1+$H20)/Параметры!$C$5,0)*Параметры!$C$5) -> 375000 | J20: =IF(F20="","",ROUND(F20*(1+$H20)/Параметры!$C$5,0)*Параметры!$C$5) -> 330000 | K20: — | L20: 9 (на каждой) | M20: 4 (на каждой) | N20: 10 (суммарно) | O20: до 10 | P20: 5 | Q20: Брендирование, печать меню, вывоз мусора, разрешение | R20: Оферта | V20: =IF(N(I20)*N(T20)+N(J20)*N(U20)=0,"",N(I20)*N(T20)+N(J20)*N(U20))
B21: Корнер №3 | C21: Комбо (1+2) | D21: Ж+Ж / Д+Д | E21: 360000 | F21: 320000 | G21: пакет | H21: =Параметры!$C$4 -> 0.1 | I21: =IF(E21="","",ROUND(E21*(1+$H21)/Параметры!$C$5,0)*Параметры!$C$5) -> 395000 | J21: =IF(F21="","",ROUND(F21*(1+$H21)/Параметры!$C$5,0)*Параметры!$C$5) -> 350000 | K21: — | L21: 9 (на каждой) | M21: 4 (на каждой) | N21: 15 (суммарно) | O21: до 15 | P21: 10 | Q21: Брендирование, печать меню, вывоз мусора, разрешение | R21: Оферта | S21: Деление выручки | V21: =IF(N(I21)*N(T21)+N(J21)*N(U21)=0,"",N(I21)*N(T21)+N(J21)*N(U21))
B22: ВИП-корнер | C22: Комбо (1+2) | D22: — | E22: 390000 | G22: пакет | H22: =Параметры!$C$4 -> 0.1 | I22: =IF(E22="","",ROUND(E22*(1+$H22)/Параметры!$C$5,0)*Параметры!$C$5) -> 430000 | J22: =IF(F22="","",ROUND(F22*(1+$H22)/Параметры!$C$5,0)*Параметры!$C$5) | K22: — | L22: 9 (на каждой) | M22: 4 (на каждой) | N22: 10 (суммарно) | O22: до 10 | P22: 7 | Q22: Брендирование, печать меню, вывоз мусора | R22: Оферта | S22: Договор бар ВИП | V22: =IF(N(I22)*N(T22)+N(J22)*N(U22)=0,"",N(I22)*N(T22)+N(J22)*N(U22))
B23: Двойной корнер лаер | C23: Москва | D23: Ж+Ж (2 варианта) | E23: 450000 | F23: 475000 | G23: пакет | H23: =Параметры!$C$4 -> 0.1 | I23: =IF(E23="","",ROUND(E23*(1+$H23)/Параметры!$C$5,0)*Параметры!$C$5) -> 495000 | J23: =IF(F23="","",ROUND(F23*(1+$H23)/Параметры!$C$5,0)*Параметры!$C$5) -> 525000 | R23: Оферта | S23: Деление выручки | V23: =IF(N(I23)*N(T23)+N(J23)*N(U23)=0,"",N(I23)*N(T23)+N(J23)*N(U23))
B24: Двойной корнер лаер | C24: Санкт-Петербург | D24: Ж+Ж (2 варианта) | E24: 410000 | F24: 435000 | G24: пакет | H24: =Параметры!$C$4 -> 0.1 | I24: =IF(E24="","",ROUND(E24*(1+$H24)/Параметры!$C$5,0)*Параметры!$C$5) -> 450000 | J24: =IF(F24="","",ROUND(F24*(1+$H24)/Параметры!$C$5,0)*Параметры!$C$5) -> 480000 | R24: Оферта | S24: Деление выручки | V24: =IF(N(I24)*N(T24)+N(J24)*N(U24)=0,"",N(I24)*N(T24)+N(J24)*N(U24))
B25: Комбо лаер + дерево, 5 кВт | C25: Комбо (1+2) | D25: Ж+Д | E25: 350000 | G25: пакет | H25: =Параметры!$C$4 -> 0.1 | I25: =IF(E25="","",ROUND(E25*(1+$H25)/Параметры!$C$5,0)*Параметры!$C$5) -> 385000 | J25: =IF(F25="","",ROUND(F25*(1+$H25)/Параметры!$C$5,0)*Параметры!$C$5) | N25: 5 | R25: Оферта | V25: =IF(N(I25)*N(T25)+N(J25)*N(U25)=0,"",N(I25)*N(T25)+N(J25)*N(U25))
B26: Комбо лаер + дерево, 10 кВт | C26: Комбо (1+2) | D26: Ж+Д | E26: 370000 | G26: пакет | H26: =Параметры!$C$4 -> 0.1 | I26: =IF(E26="","",ROUND(E26*(1+$H26)/Параметры!$C$5,0)*Параметры!$C$5) -> 405000 | J26: =IF(F26="","",ROUND(F26*(1+$H26)/Параметры!$C$5,0)*Параметры!$C$5) | N26: 10 | R26: Оферта | V26: =IF(N(I26)*N(T26)+N(J26)*N(U26)=0,"",N(I26)*N(T26)+N(J26)*N(U26))
B27: Комбо лаер + дерево, 15 кВт | C27: Комбо (1+2) | D27: Ж+Д | E27: 390000 | G27: пакет | H27: =Параметры!$C$4 -> 0.1 | I27: =IF(E27="","",ROUND(E27*(1+$H27)/Параметры!$C$5,0)*Параметры!$C$5) -> 430000 | J27: =IF(F27="","",ROUND(F27*(1+$H27)/Параметры!$C$5,0)*Параметры!$C$5) | N27: 15 | R27: Оферта | S27: Деление выручки | V27: =IF(N(I27)*N(T27)+N(J27)*N(U27)=0,"",N(I27)*N(T27)+N(J27)*N(U27))
B28: Двойной дерево | C28: Комбо (1+2) | D28: Д+Д (2 варианта) | E28: 350000 | F28: 370000 | G28: пакет | H28: =Параметры!$C$4 -> 0.1 | I28: =IF(E28="","",ROUND(E28*(1+$H28)/Параметры!$C$5,0)*Параметры!$C$5) -> 385000 | J28: =IF(F28="","",ROUND(F28*(1+$H28)/Параметры!$C$5,0)*Параметры!$C$5) -> 405000 | R28: Оферта | V28: =IF(N(I28)*N(T28)+N(J28)*N(U28)=0,"",N(I28)*N(T28)+N(J28)*N(U28))
B29: СПЕЦИАЛЬНЫЕ И ДОПОЛНИТЕЛЬНЫЕ ФОРМАТЫ
B30: Застройка своего корнера | C30: Любая | D30: Свой макет | E30: 18000 | G30: за кв.м | H30: =Параметры!$C$4 -> 0.1 | I30: =IF(E30="","",ROUND(E30*(1+$H30)/100,0)*100) -> 19800 | J30: =IF(F30="","",ROUND(F30*(1+$H30)/100,0)*100) | K30: — | L30: По макету | M30: — | N30: до 10 | O30: — | P30: — | Q30: Размещение на сайте, вывоз мусора, общая зона | R30: Оферта | V30: =IF(N(I30)*N(T30)+N(J30)*N(U30)=0,"",N(I30)*N(T30)+N(J30)*N(U30))
B31: Dark Kitchen | C31: Москва | D31: — | E31: 390000 | G31: пакет | H31: =Параметры!$C$4 -> 0.1 | I31: =IF(E31="","",ROUND(E31*(1+$H31)/Параметры!$C$5,0)*Параметры!$C$5) -> 430000 | J31: =IF(F31="","",ROUND(F31*(1+$H31)/Параметры!$C$5,0)*Параметры!$C$5) | K31: — | L31: Стойка 2x2, шатер 5x5 | M31: — | N31: до 15 | O31: до 15 | P31: — | Q31: Промо-поддержка, вывоз мусора | R31: Оферта | S31: Деление выручки | V31: =IF(N(I31)*N(T31)+N(J31)*N(U31)=0,"",N(I31)*N(T31)+N(J31)*N(U31))
B32: Dark Kitchen | C32: Санкт-Петербург | D32: — | E32: 290000 | G32: пакет | H32: =Параметры!$C$4 -> 0.1 | I32: =IF(E32="","",ROUND(E32*(1+$H32)/Параметры!$C$5,0)*Параметры!$C$5) -> 320000 | J32: =IF(F32="","",ROUND(F32*(1+$H32)/Параметры!$C$5,0)*Параметры!$C$5) | K32: — | L32: Стойка 2x2, шатер 5x5 | M32: — | N32: до 15 | O32: до 15 | P32: — | Q32: Промо-поддержка, вывоз мусора | R32: Оферта | S32: Деление выручки | V32: =IF(N(I32)*N(T32)+N(J32)*N(U32)=0,"",N(I32)*N(T32)+N(J32)*N(U32))
B33: Grab & Go (Вендинг) | C33: Москва | D33: — | E33: 100000 | G33: пакет | H33: =Параметры!$C$4 -> 0.1 | I33: =IF(E33="","",ROUND(E33*(1+$H33)/Параметры!$C$5,0)*Параметры!$C$5) -> 110000 | J33: =IF(F33="","",ROUND(F33*(1+$H33)/Параметры!$C$5,0)*Параметры!$C$5) | K33: — | L33: 2 (автомат) | M33: — | N33: 3 | O33: — | P33: — | Q33: Вывоз мусора | R33: Оферта | V33: =IF(N(I33)*N(T33)+N(J33)*N(U33)=0,"",N(I33)*N(T33)+N(J33)*N(U33))
B34: Grab & Go (Вендинг) | C34: Санкт-Петербург | D34: — | E34: 80000 | G34: пакет | H34: =Параметры!$C$4 -> 0.1 | I34: =IF(E34="","",ROUND(E34*(1+$H34)/Параметры!$C$5,0)*Параметры!$C$5) -> 90000 | J34: =IF(F34="","",ROUND(F34*(1+$H34)/Параметры!$C$5,0)*Параметры!$C$5) | K34: — | L34: 2 (автомат) | M34: — | N34: 3 | O34: — | P34: — | Q34: Вывоз мусора | R34: Оферта | V34: =IF(N(I34)*N(T34)+N(J34)*N(U34)=0,"",N(I34)*N(T34)+N(J34)*N(U34))
B35: Лавка. Фермерский рынок | C35: Москва | D35: — | E35: 115000 | G35: пакет | H35: =Параметры!$C$4 -> 0.1 | I35: =IF(E35="","",ROUND(E35*(1+$H35)/Параметры!$C$5,0)*Параметры!$C$5) -> 125000 | J35: =IF(F35="","",ROUND(F35*(1+$H35)/Параметры!$C$5,0)*Параметры!$C$5) | K35: — | L35: 4 | M35: — | N35: 2 | O35: до 2 | P35: — | Q35: Вывоз мусора | R35: Оферта | V35: =IF(N(I35)*N(T35)+N(J35)*N(U35)=0,"",N(I35)*N(T35)+N(J35)*N(U35))
B36: Лавка. Фермерский рынок | C36: Санкт-Петербург | D36: — | E36: 90000 | G36: пакет | H36: =Параметры!$C$4 -> 0.1 | I36: =IF(E36="","",ROUND(E36*(1+$H36)/Параметры!$C$5,0)*Параметры!$C$5) -> 100000 | J36: =IF(F36="","",ROUND(F36*(1+$H36)/Параметры!$C$5,0)*Параметры!$C$5) | K36: — | L36: 4 | M36: — | N36: 2 | O36: до 2 | P36: — | Q36: Вывоз мусора | R36: Оферта | V36: =IF(N(I36)*N(T36)+N(J36)*N(U36)=0,"",N(I36)*N(T36)+N(J36)*N(U36))
B37: Гастропартнер ВИП-фудкорта | C37: Москва | D37: — | E37: 900000 | G37: пакет | H37: =Параметры!$C$4 -> 0.1 | I37: =IF(E37="","",ROUND(E37*(1+$H37)/Параметры!$C$5,0)*Параметры!$C$5) -> 990000 | J37: =IF(F37="","",ROUND(F37*(1+$H37)/Параметры!$C$5,0)*Параметры!$C$5) | K37: — | L37: ≥5 точек | M37: — | N37: до 30 | O37: до 5 | P37: 2 | Q37: Вывоз мусора | R37: Деление выручки | S37: Договор бар ВИП | V37: =IF(N(I37)*N(T37)+N(J37)*N(U37)=0,"",N(I37)*N(T37)+N(J37)*N(U37))
B38: Гастропартнер ВИП-фудкорта | C38: Санкт-Петербург | D38: — | E38: 750000 | G38: пакет | H38: =Параметры!$C$4 -> 0.1 | I38: =IF(E38="","",ROUND(E38*(1+$H38)/Параметры!$C$5,0)*Параметры!$C$5) -> 825000 | J38: =IF(F38="","",ROUND(F38*(1+$H38)/Параметры!$C$5,0)*Параметры!$C$5) | K38: — | L38: ≥5 точек | M38: — | N38: до 30 | O38: до 5 | P38: 2 | Q38: Вывоз мусора | R38: Деление выручки | S38: Договор бар ВИП | V38: =IF(N(I38)*N(T38)+N(J38)*N(U38)=0,"",N(I38)*N(T38)+N(J38)*N(U38))
B39: Технологический партнер | C39: Москва | D39: — | E39: 540000 | G39: пакет | H39: =Параметры!$C$4 -> 0.1 | I39: =IF(E39="","",ROUND(E39*(1+$H39)/Параметры!$C$5,0)*Параметры!$C$5) -> 595000 | J39: =IF(F39="","",ROUND(F39*(1+$H39)/Параметры!$C$5,0)*Параметры!$C$5) | K39: — | L39: — | M39: — | N39: — | O39: — | P39: — | Q39: Эксклюзив, брендирование, статус | R39: Гастроспонсорство | V39: =IF(N(I39)*N(T39)+N(J39)*N(U39)=0,"",N(I39)*N(T39)+N(J39)*N(U39))
B40: Технологический партнер | C40: Санкт-Петербург | D40: — | E40: 300000 | G40: пакет | H40: =Параметры!$C$4 -> 0.1 | I40: =IF(E40="","",ROUND(E40*(1+$H40)/Параметры!$C$5,0)*Параметры!$C$5) -> 330000 | J40: =IF(F40="","",ROUND(F40*(1+$H40)/Параметры!$C$5,0)*Параметры!$C$5) | K40: — | L40: — | M40: — | N40: — | O40: — | P40: — | Q40: Эксклюзив, брендирование, статус | R40: Гастроспонсорство | V40: =IF(N(I40)*N(T40)+N(J40)*N(U40)=0,"",N(I40)*N(T40)+N(J40)*N(U40))
B41: Интеграция локальных фестивалей | C41: — | D41: — | E41: 732000 | G41: пакет | H41: =Параметры!$C$4 -> 0.1 | I41: =IF(E41="","",ROUND(E41*(1+$H41)/Параметры!$C$5,0)*Параметры!$C$5) -> 805000 | J41: =IF(F41="","",ROUND(F41*(1+$H41)/Параметры!$C$5,0)*Параметры!$C$5) | K41: — | L41: 5 корнеров 3x3 | M41: — | N41: до 30 | O41: — | P41: — | Q41: Проведение активностей, вывоз мусора | R41: Гастроспонсорство | S41: Оферта | V41: =IF(N(I41)*N(T41)+N(J41)*N(U41)=0,"",N(I41)*N(T41)+N(J41)*N(U41))
...

Sheet Форматы договоров
B1: Форматы договоров с резидентами и партнёрами — 2027
B2: Рабочая структура для юриста, не готовый текст договора. Ссылки на законы — для проверки юристом, финальные формулировки согласовать с юр. отделом Афиши.
B4: Параметр | C4: 1. Публичная оферта на участие | D4: 2. Договор на торговлю напитками (бар ВИП) | E4: 3. Договор на деление выручки с резидентом | F4: 4. Договор гастроспонсорства
B5: Когда применять | C5: Стандартные пакеты с фиксированной ценой: корнеры, фудтраки, Dark Kitchen, вендинг, лавки, тележки, доп. опции. Массовый поток резидентов. | D5: Эксклюзивный оператор бара / напитков в ВИП-зоне, лаунж-зоне, ВИП-фудкорте. | E5: Сильные резиденты с высоким чеком, где фикс отпугивает, а потенциал выручки выше цены пакета; новые форматы без истории продаж. | F5: Бренды и партнёры без торговли или с торговлей как частью интеграции: тех. партнёр, коллаборации брендов, интеграция локальных фестивалей, спецпроекты.
B6: Пакеты из матрицы | C6: Все строки с форматом «Оферта» | D6: ВИП-корнер, Лаунж-зона, Гастропартнер ВИП-фудкорта (альтернатива) | E6: Корнер №3–4, двойные корнеры, Фудтрак, Dark Kitchen, Гастропартнер ВИП-фудкорта | F6: Технологический партнер, Коллаборация брендов, Интеграция локальных фестивалей
B7: Правовая форма | C7: Публичная оферта (ст. 435, 437 ГК РФ); акцепт — оплата счёта / заполнение заявки (ст. 438 п. 3 ГК РФ). Договор возмездного оказания услуг (гл. 39 ГК РФ). | D7: Двусторонний договор: предоставление права торговли / услуги организатора + исключительность категории. Иногда — субаренда места (если организатор арендует площадку). | E7: Договор оказания услуг с переменным вознаграждением (% от выручки) + минимальная гарантия. Альтернатива — агентский договор, если оплаты идут через кассу/эквайринг организатора. Договор простого товарищества (гл. 55 ГК) не рекомендуется: сложный учёт и налоги. | F7: Договор спонсорства = договор на оказание рекламных услуг (ФЗ «О рекламе» № 38-ФЗ, ст. 3 п. 9–10). Возможен смешанный: деньги + бартер (товар/услуги).
B8: Стороны | C8: Организатор ↔ резидент (ИП / ООО / самозанятый — проверить, разрешена ли торговля для его режима). | D8: Организатор ↔ оператор бара (юрлицо/ИП с правом продажи алкоголя). | E8: Организатор ↔ резидент. | F8: Организатор ↔ спонсор (бренд) или его рекламное агентство.
B9: Предмет | C9: Предоставление места и пакета услуг на фестивале (застройка, электричество, аккредитация, вывоз мусора и т.д. — по матрице). | D9: Право на эксклюзивную продажу напитков в ВИП-зоне, место, застройка бара, подключения; оператор — продажа, персонал, лицензии. | E9: Предоставление места и услуг; вознаграждение организатора — % от выручки точки. | F9: Рекламные и интеграционные услуги: упоминание статуса, брендирование, зона/активация, контент, эксклюзивность категории.
B10: Цена / вознаграждение | C10: Фикс по матрице 2027. | D10: Фикс за право + % от выручки, либо MAX(минимальная гарантия; % от выручки). Ориентир — лист «Калькулятор». | E10: MAX(минимальная гарантия; % × выручка). База — ВЫРУЧКА, не прибыль: прибыль резидента организатор проверить не может. | F10: Фикс спонсорского взноса (деньги) + оценка бартера. Пакетные уровни: генеральный / официальный / партнёр.
B11: Порядок оплаты | C11: Предоплата (Параметры: 50%) при акцепте; остаток — до дедлайна (напр. за 30 дней до фестиваля). Без 100% оплаты — нет допуска к монтажу. | D11: Минимальная гарантия — авансом до монтажа; % — по итогам, в течение 5–10 раб. дней после отчёта. | E11: Минимальная гарантия — авансом; доплата % — после сверки выручки. | F11: По графику: 50% при подписании, 50% до старта фестиваля; бартер — по акту приёма-передачи.
B12: Учёт выручки / контроль | C12: Не нужен. | D12: Обязательно: выгрузка из кассы (ОФД) / эквайринга за каждый день. Право организатора на аудит. Лучше — единый эквайринг/кассовая система фестиваля. | E12: Обязательно: ежедневный Z-отчёт, выгрузка ОФД, доступ к данным эквайринга. Санкция за сокрытие выручки (штраф, расчёт по средней). | F12: Отчёт организатора: охваты, контент, фото-отчёт, количество контактов — по KPI договора.
B13: Лицензии и разрешения | C13: Резидент: ККТ (54-ФЗ), документы на продукцию, санитарные требования, мед. книжки персонала. | D13: Розничная продажа алкоголя (кроме пива, сидра, медовухи) — по лицензии (171-ФЗ); ЕГАИС; региональные ограничения продажи алкоголя на массовых мероприятиях — проверить для Москвы и СПб под конкретную площадку и даты. | E13: Как в оферте + ККТ резидента обязательна (иначе выручку не проверить). | F13: Если спонсор торгует — как в оферте. Маркировка рекламы (ERID) для онлайн-размещений по 38-ФЗ.
B14: Обязанности организатора | C14: Место, застройка, подключения, аккредитация, разрешения, вывоз мусора — по пакету. | D14: Эксклюзив категории напитков в ВИП-зоне (запрет конкурентов), застройка бара, логистика, ВИП-трафик. | E14: Место, услуги, трафик, промо резидента. | F14: Выполнение рекламного пакета, эксклюзив категории, отчёт.
B15: Обязанности контрагента | C15: Своевременная оплата, соблюдение правил площадки, тайминга монтажа/демонтажа, санитарии, меню по согласованию. | D15: Ассортимент и цены по согласованию, стандарты сервиса, персонал, лицензии, соблюдение запрета продажи несовершеннолетним. | E15: Работа все дни фестиваля, согласованное меню и цены, отчётность, использование ККТ. | F15: Оплата, предоставление материалов (логотипы, макеты) в сроки, согласование активаций.
... B21: Приложения к договору | C21: Состав пакета (из матрицы), план площадки, правила для резидентов, тайминг монтажа/демонтажа, шкала штрафов. | D21: Ассортимент и цены, план бара, стандарты сервиса, форма ежедневного отчёта. | E21: Форма отчёта о выручке, порядок сверки, состав пакета. | F21: Спонсорский пакет, медиаплан, макеты, форма отчёта, акт бартера.

Sheet Калькулятор
B1: Калькулятор: фикс vs деление выручки
B2: Значения в жёлтых ячейках — пример для проверки формата, замените своими цифрами (выручку берите из факта 2026).
B4: Бар ВИП (пример)
B5: Прогноз выручки точки за фестиваль, ₽ | C5: 3000000
B6: Доля организатора, % | C6: =Параметры!$C$9 -> 0.25
B7: Минимальная гарантия, ₽ | C7: 400000
B8: Цена фикс-пакета для сравнения, ₽ | C8: 250000
B9: Доход организатора по % (без гарантии), ₽ | C9: =C5*C6 -> 750000
B10: Доход организатора с гарантией = MAX(гарантия; %), ₽ | C10: =MAX(C7,C5*C6) -> 750000
B11: Разница с фикс-пакетом, ₽ | C11: =C10-C8 -> 500000
B12: Выручка точки, при которой % = фикс, ₽ | C12: =IF(C6=0,"",C8/C6) -> 1000000
B13: Вывод | C13: =IF(C11>=0,"Деление выгоднее или равно фиксу","Фикс выгоднее для организатора") -> Деление выгоднее или равно фиксу
B16: Деление выручки с резидентом (пример: Корнер №4, Москва)
B17: Прогноз выручки точки за фестиваль, ₽ | C17: 1500000
B18: Доля организатора, % | C18: =Параметры!$C$8 -> 0.2
B19: Минимальная гарантия, ₽ | C19: 200000
B20: Цена фикс-пакета для сравнения, ₽ | C20: ='Матрица 2027'!I9 -> 310000
B21: Доход организатора по % (без гарантии), ₽ | C21: =C17*C18 -> 300000
B22: Доход организатора с гарантией = MAX(гарантия; %), ₽ | C22: =MAX(C19,C17*C18) -> 300000
B23: Разница с фикс-пакетом, ₽ | C23: =C22-C20 -> -10000
B24: Выручка точки, при которой % = фикс, ₽ | C24: =IF(C18=0,"",C20/C18) -> 1550000
B25: Вывод | C25: =IF(C23>=0,"Деление выгоднее или равно фиксу","Фикс выгоднее для организатора") -> Фикс выгоднее для организатора

Sheet Резиденты — уровни
B1: Резиденты 2027: уровни A / B / C — кто нам нужен и зачем
B2: Определения, скоринг и таймлайн. Меняйте жёлтые ячейки (веса и пороги). Целевые количества — лист «Резиденты — план», сам список — «Резиденты — лонг-лист».
B4: Параметр | C4: A — якоря / хедлайнеры | D4: B — основа фестиваля | E4: C — разнообразие и ниша | H4: Справочник: пакеты | I4: Справочник: категории | J4: Справочник: статусы
B5: Роль на фестивале | C5: Приводят аудиторию и прессу. Лицо фестиваля в анонсах, на афише и в PR. Повышают статус площадки для остальных резидентов и спонсоров. | D5: Делают основную выручку и стабильный поток гостей. Закрывают ключевые категории еды все дни фестиваля. | E5: Дают разнообразие, новизну, «открытия». Закрывают нишевые категории (десерты, кофе, фермерские продукты, напитки) и заполняют площадку. | H5: Корнер №1 | I5: Бургеры / стритфуд | J5: Лонг-лист
B6: Критерии отбора | C6: Балл скоринга ≥ порога A. Известный бренд / шеф федерального или городского уровня; сильная медийность; высокий чек; надёжная операционка на потоке; готовность к коллаборациям и спецменю. | D6: Балл между порогами B и A. Известны в своём городе; подтверждённая выручка на фестивалях / в 2026; понятная массовая кухня; соблюдают тайминг и стандарты. | E6: Балл ниже порога B. Молодые проекты, фермеры, локальные производители, узкие форматы. Обязательно: уникальность для площадки и соответствие санитарным требованиям. | H6: Корнер №2 | I6: Азиатская | J6: Переговоры
B7: Типичные пакеты | C7: Корнер №3–4, двойные корнеры, ВИП-корнер, Гастропартнер ВИП-фудкорта, коллаборации брендов, оператор бара ВИП | D7: Корнер №2–3, комбопакеты, фудтрак, Dark Kitchen | E7: Корнер №1, Лавка. Фермерский рынок, тележка для мороженого, Grab & Go | H7: Корнер №3 | I7: Кавказская | J7: КП отправлено
B8: Формат договора | C8: Индивидуальный договор: деление выручки с минимальной гарантией, договор бар ВИП, коллаборация/спонсорство | D8: Оферта (основной), деление выручки — как исключение для сильных B | E8: Оферта, 100% предоплата | H8: Корнер №4 | I8: Итальянская / Европа | J8: Подписан
B9: Что предлагаем | C9: Лучшие места (право выбора без доплаты), анонс в первой волне, спецпроекты (Гастрогостиная, коллаборации), гибкая модель оплаты, ВИП-аккредитации | D9: Скидка за раннюю оплату, комбопакет Москва + СПб, место в основном потоке, включение в общие анонсы | E9: Отбор через опенколл, базовый пакет, промо в блоке «Новые имена», допопции за доплату | H9: ВИП-корнер | I9: Мясо / гриль / BBQ | J9: Оплачен
B10: Целевая доля точек | C10: ≈ 15–20% | D10: ≈ 45–50% | E10: ≈ 30–35% | H10: Фудтрак | I10: Морепродукты | J10: Отказ
B11: Когда закрываем | C11: Переговоры ноябрь 2026 – январь 2027, подписание до 15 февраля | D11: Открытие продаж — февраль, основная волна март–апрель | E11: Опенколл март–май, добор до заполнения площадки | H11: Двойной корнер лаер | I11: Здоровая / веган
B12: Ответственный (вписать) | H12: Комбо лаер + дерево, 5 кВт | I12: Десерты / выпечка
B13: Главные риски | C13: Высокие требования к условиям; позднее подтверждение; зависимость анонсов от 2–3 имён | D13: Однотипность меню (дубли категорий); сдвиг оплат к дедлайну | E13: Слабая операционка на потоке; низкая выручка → отказ на следующий сезон | H13: Комбо лаер + дерево, 10 кВт | I13: Кофе
B14: KPI уровня | C14: Подписано до 15.02; упоминания в СМИ; выручка/кв.м; продление на 2028 | D14: Оплата до дедлайна; выручка на точку; доля повторных резидентов | E14: Заполнение категорий; доля новых имён; оценка гостей / отсутствие нарушений | H14: Комбо лаер + дерево, 15 кВт | I14: Безалкогольные напитки
H15: Двойной дерево | I15: Бар / алкоголь
H16: Застройка своего корнера | I16: Фермерские продукты
B17: Скоринг резидента (оценка 1–5 по каждому критерию) | H17: Dark Kitchen | I17: Мороженое
B18: Критерий | C18: Вес | D18: 1 балл | E18: 3 балла | F18: 5 баллов | H18: Grab & Go (Вендинг) | I18: Другое
B19: Узнаваемость бренда | C19: 0.25 | D19: Новый / неизвестный проект | E19: Известен в своём городе | F19: Федеральный бренд / известный шеф | H19: Лавка. Фермерский рынок
B20: Средний чек | C20: 0.15 | D20: Ниже среднего по фестивалю | E20: На уровне среднего | F20: Значительно выше среднего | H20: Гастропартнер ВИП-фудкорта
B21: Выручка на фестивалях (2026 или аналоги) | C21: 0.2 | D21: Нет данных / слабая | E21: Средняя по площадке | F21: Топ-10 по площадке | H21: Коллаборация Бренд №1 х №2
B22: Медийность (соцсети, пресса) | C22: 0.15 | D22: Почти нет аудитории | E22: Активные соцсети, локальная пресса | F22: Большая аудитория, сам приносит охват | H22: Лаунж-зона для бронирования
B23: Операционная надёжность | C23: 0.15 | D23: Опыта потока нет / были нарушения | E23: Опыт фестивалей без серьёзных нарушений | F23: Отлаженная работа на потоке, соблюдение стандартов | H23: Тележка для мороженого
B24: Уникальность для площадки | C24: 0.1 | D24: Дублирует имеющихся | E24: Частично новая категория | F24: Закрывает пустую категорию / эксклюзив
B25: Сумма весов (должна быть 100%) | C25: =SUM(C19:C24) -> 1
B27: Порог уровня A (балл ≥) | C27: 4
B28: Порог уровня B (балл ≥), ниже — C | C28: 3
B29: Итоговый уровень можно переопределить вручную в лонг-листе (стратегическое решение важнее балла — но фиксируйте причину в комментарии).
B32: Таймлайн набора резидентов 2027
B33: Период | C33: A | D33: B | E33: C
B34: Октябрь–ноябрь 2026 | C34: Аналитика 2026 (выручка, нарушения, отзывы); лонг-лист A; первые встречи | D34: Скоринг резидентов 2026, письма о продлении | E34: Сбор базы новых проектов (соцсети, маркеты, рекомендации)
B35: Декабрь 2026 – январь 2027 | C35: Переговоры, индивидуальные условия, коллаборации | D35: Предзапись на раннюю оплату | E35: Подготовка опенколла (форма, критерии)
B36: Февраль 2027 | C36: Подписание до 15.02, анонс первой волны | D36: Публикация оферты, старт продаж, early bird до 01.03 | E36: —
B37: Март–апрель 2027 | C37: Спецпроекты, меню, контент | D37: Основная волна оплат; контроль дублей категорий | E37: Опенколл, отбор, оферта
B38: Май 2027 | C38: Финальное меню, тех. райдеры | D38: Дедлайн 100% оплаты | E38: Добор в пустые категории; лист ожидания
B39: Июнь 2027 – фестиваль | C39: Медиа-поддержка, ВИП | D39: Онбординг, тайминг монтажа | E39: Онбординг, контроль санитарии
B40: Даты фестиваля 2027 в файле не указаны — сдвиньте таймлайн под утверждённые даты.

Sheet Резиденты — план
B1: План резидентов 2027 по уровням: цель vs факт
B2: Цели (жёлтые) — моё предложение для старта, не утверждённые цифры. «Факт» = резиденты со статусом «Подписан» или «Оплачен» в лонг-листе; комбопакеты учитываются в обоих городах.
B4: 1. Целевой состав по форматам
B5: Формат | C5: Мск A | D5: Мск B | E5: Мск C | F5: Мск итого | G5: Мск: мест по плану площадки | H5: Мск остаток | I5: СПб A | J5: СПб B | K5: СПб C | L5: СПб итого | M5: СПб: мест по плану площадки | N5: СПб остаток
B6: Корнеры (№1–4, двойные, комбо) | C6: 3 | D6: 13 | E6: 4 | F6: =SUM(C6:E6) -> 20 | H6: =IF(G6="","",G6-F6) | I6: 2 | J6: 10 | K6: 3 | L6: =SUM(I6:K6) -> 15 | N6: =IF(M6="","",M6-L6)
B7: ВИП-корнер / Гастропартнер ВИП-фудкорта | C7: 2 | D7: 2 | E7: 0 | F7: =SUM(C7:E7) -> 4 | H7: =IF(G7="","",G7-F7) | I7: 2 | J7: 1 | K7: 0 | L7: =SUM(I7:K7) -> 3 | N7: =IF(M7="","",M7-L7)
B8: Фудтрак | C8: 0 | D8: 0 | E8: 0 | F8: =SUM(C8:E8) -> 0 | H8: =IF(G8="","",G8-F8) | I8: 0 | J8: 2 | K8: 1 | L8: =SUM(I8:K8) -> 3 | N8: =IF(M8="","",M8-L8)
B9: Dark Kitchen | C9: 0 | D9: 1 | E9: 0 | F9: =SUM(C9:E9) -> 1 | H9: =IF(G9="","",G9-F9) | I9: 0 | J9: 1 | K9: 0 | L9: =SUM(I9:K9) -> 1 | N9: =IF(M9="","",M9-L9)
B10: Лавка. Фермерский рынок | C10: 0 | D10: 1 | E10: 5 | F10: =SUM(C10:E10) -> 6 | H10: =IF(G10="","",G10-F10) | I10: 0 | J10: 1 | K10: 4 | L10: =SUM(I10:K10) -> 5 | N10: =IF(M10="","",M10-L10)
B11: Grab & Go (Вендинг) | C11: 0 | D11: 0 | E11: 2 | F11: =SUM(C11:E11) -> 2 | H11: =IF(G11="","",G11-F11) | I11: 0 | J11: 0 | K11: 1 | L11: =SUM(I11:K11) -> 1 | N11: =IF(M11="","",M11-L11)
B12: Тележка для мороженого | C12: 0 | D12: 0 | E12: 2 | F12: =SUM(C12:E12) -> 2 | H12: =IF(G12="","",G12-F12) | I12: 0 | J12: 0 | K12: 2 | L12: =SUM(I12:K12) -> 2 | N12: =IF(M12="","",M12-L12)
B13: Оператор бара ВИП / напитки | C13: 1 | D13: 0 | E13: 0 | F13: =SUM(C13:E13) -> 1 | H13: =IF(G13="","",G13-F13) | I13: 1 | J13: 0 | K13: 0 | L13: =SUM(I13:K13) -> 1 | N13: =IF(M13="","",M13-L13)
B14: Коллаборации брендов | C14: 1 | D14: 0 | E14: 0 | F14: =SUM(C14:E14) -> 1 | H14: =IF(G14="","",G14-F14) | I14: 1 | J14: 0 | K14: 0 | L14: =SUM(I14:K14) -> 1 | N14: =IF(M14="","",M14-L14)
B15: ИТОГО | C15: =SUM(C6:C14) -> 7 | D15: =SUM(D6:D14) -> 17 | E15: =SUM(E6:E14) -> 13 | F15: =SUM(F6:F14) -> 37 | G15: =SUM(G6:G14) -> 0 | H15: =IF(COUNT(H6:H14)=0,"",SUM(H6:H14)) | I15: =SUM(I6:I14) -> 6 | J15: =SUM(J6:J14) -> 15 | K15: =SUM(K6:K14) -> 11 | L15: =SUM(L6:L14) -> 32 | M15: =SUM(M6:M14) -> 0 | N15: =IF(COUNT(N6:N14)=0,"",SUM(N6:N14))
B16: Доля уровня в составе | C16: =IF(F15=0,0,C15/F15) -> 0.18918919 | D16: =IF(F15=0,0,D15/F15) -> 0.45945946 | E16: =IF(F15=0,0,E15/F15) -> 0.35135135 | I16: =IF(L15=0,0,I15/L15) -> 0.1875 | J16: =IF(L15=0,0,J15/L15) -> 0.46875 | K16: =IF(L15=0,0,K15/L15) -> 0.34375
B17: Отрицательный остаток = целей больше, чем мест на плане площадки. Заполните колонки «мест по плану площадки».
B19: 2. План / факт по уровням
B20: Уровень | C20: Мск план | D20: Мск факт | E20: Мск % | F20: СПб план | G20: СПб факт | H20: СПб % | I20: В работе (переговоры + КП) | J20: Выручка подписанных ₽ | K20: Отказы
B21: A | C21: =C15 -> 7 | D21: =COUNTIFS('Резиденты — лонг-лист'!$Q$5:$Q$204,"A",'Резиденты — лонг-лист'!$D$5:$D$204,"Москва",'Резиденты — лонг-лист'!$S$5:$S$204,"Подписан")+COUNTIFS('Резиденты — лонг-лист'!$Q$5:$Q$204,"A",'Резиденты — лонг-лист'!$D$5:$D$204,"Москва",'Резиденты — лонг-лист'!$S$5:$S$204,"Оплачен")+COUNTIFS('Резиденты — лонг-лист'!$Q$5:$Q$204,"A",'Резиденты — лонг-лист'!$D$5:$D$204,"Комбо (1+2)",'Резиденты — лонг-лист'!$S$5:$S$204,"Подписан")+COUNTIFS('Резиденты — лонг-лист'!$Q$5:$Q$204,"A",'Резиденты — лонг-лист'!$D$5:$D$204,"Комбо (1+2)",'Резиденты — лонг-лист'!$S$5:$S$204,"Оплачен") -> 0 | E21: =IF(C21=0,"",D21/C21) -> 0 | F21: =I15 -> 6 | G21: =COUNTIFS('Резиденты — лонг-лист'!$Q$5:$Q$204,"A",'Резиденты — лонг-лист'!$D$5:$D$204,"Санкт-Петербург",'Резиденты — лонг-лист'!$S$5:$S$204,"Подписан")+COUNTIFS('Резиденты — лонг-лист'!$Q$5:$Q$204,"A",'Резиденты — лонг-лист'!$D$5:$D$204,"Санкт-Петербург",'Резиденты — лонг-лист'!$S$5:$S$204,"Оплачен")+COUNTIFS('Резиденты — лонг-лист'!$Q$5:$Q$204,"A",'Резиденты — лонг-лист'!$D$5:$D$204,"Комбо (1+2)",'Резиденты — лонг-лист'!$S$5:$S$204,"Подписан")+COUNTIFS('Резиденты — лонг-лист'!$Q$5:$Q$204,"A",'Резиденты — лонг-лист'!$D$5:$D$204,"Комбо (1+2)",'Резиденты — лонг-лист'!$S$5:$S$204,"Оплачен") -> 0 | H21: =IF(F21=0,"",G21/F21) -> 0 | I21: =COUNTIFS('Резиденты — лонг-лист'!$Q$5:$Q$204,"A",'Резиденты — лонг-лист'!$S$5:$S$204,"Переговоры")+COUNTIFS('Резиденты — лонг-лист'!$Q$5:$Q$204,"A",'Резиденты — лонг-лист'!$S$5:$S$204,"КП отправлено") -> 1 | J21: =SUMIFS('Резиденты — лонг-лист'!$U$5:$U$204,'Резиденты — лонг-лист'!$Q$5:$Q$204,"A",'Резиденты — лонг-лист'!$S$5:$S$204,"Подписан")+SUMIFS('Резиденты — лонг-лист'!$U$5:$U$204,'Резиденты — лонг-лист'!$Q$5:$Q$204,"A",'Резиденты — лонг-лист'!$S$5:$S$204,"Оплачен") -> 0 | K21: =COUNTIFS('Резиденты — лонг-лист'!$Q$5:$Q$204,"A",'Резиденты — лонг-лист'!$S$5:$S$204,"Отказ") -> 0
B22: B | C22: =D15 -> 17 | D22: =COUNTIFS('Резиденты — лонг-лист'!$Q$5:$Q$204,"B",'Резиденты — лонг-лист'!$D$5:$D$204,"Москва",'Резиденты — лонг-лист'!$S$5:$S$204,"Подписан")+COUNTIFS('Резиденты — лонг-лист'!$Q$5:$Q$204,"B",'Резиденты — лонг-лист'!$D$5:$D$204,"Москва",'Резиденты — лонг-лист'!$S$5:$S$204,"Оплачен")+COUNTIFS('Резиденты — лонг-лист'!$Q$5:$Q$204,"B",'Резиденты — лонг-лист'!$D$5:$D$204,"Комбо (1+2)",'Резиденты — лонг-лист'!$S$5:$S$204,"Подписан")+COUNTIFS('Резиденты — лонг-лист'!$Q$5:$Q$204,"B",'Резиденты — лонг-лист'!$D$5:$D$204,"Комбо (1+2)",'Резиденты — лонг-лист'!$S$5:$S$204,"Оплачен") -> 0 | E22: =IF(C22=0,"",D22/C22) -> 0 | F22: =J15 -> 15 | G22: =COUNTIFS('Резиденты — лонг-лист'!$Q$5:$Q$204,"B",'Резиденты — лонг-лист'!$D$5:$D$204,"Санкт-Петербург",'Резиденты — лонг-лист'!$S$5:$S$204,"Подписан")+COUNTIFS('Резиденты — лонг-лист'!$Q$5:$Q$204,"B",'Резиденты — лонг-лист'!$D$5:$D$204,"Санкт-Петербург",'Резиденты — лонг-лист'!$S$5:$S$204,"Оплачен")+COUNTIFS('Резиденты — лонг-лист'!$Q$5:$Q$204,"B",'Резиденты — лонг-лист'!$D$5:$D$204,"Комбо (1+2)",'Резиденты — лонг-лист'!$S$5:$S$204,"Подписан")+COUNTIFS('Резиденты — лонг-лист'!$Q$5:$Q$204,"B",'Резиденты — лонг-лист'!$D$5:$D$204,"Комбо (1+2)",'Резиденты — лонг-лист'!$S$5:$S$204,"Оплачен") -> 0 | H22: =IF(F22=0,"",G22/F22) -> 0 | I22: =COUNTIFS('Резиденты — лонг-лист'!$Q$5:$Q$204,"B",'Резиденты — лонг-лист'!$S$5:$S$204,"Переговоры")+COUNTIFS('Резиденты — лонг-лист'!$Q$5:$Q$204,"B",'Резиденты — лонг-лист'!$S$5:$S$204,"КП отправлено") -> 0 | J22: =SUMIFS('Резиденты — лонг-лист'!$U$5:$U$204,'Резиденты — лонг-лист'!$Q$5:$Q$204,"B",'Резиденты — лонг-лист'!$S$5:$S$204,"Подписан")+SUMIFS('Резиденты — лонг-лист'!$U$5:$U$204,'Резиденты — лонг-лист'!$Q$5:$Q$204,"B",'Резиденты — лонг-лист'!$S$5:$S$204,"Оплачен") -> 0 | K22: =COUNTIFS('Резиденты — лонг-лист'!$Q$5:$Q$204,"B",'Резиденты — лонг-лист'!$S$5:$S$204,"Отказ") -> 0
B23: C | C23: =E15 -> 13 | D23: =COUNTIFS('Резиденты — лонг-лист'!$Q$5:$Q$204,"C",'Резиденты — лонг-лист'!$D$5:$D$204,"Москва",'Резиденты — лонг-лист'!$S$5:$S$204,"Подписан")+COUNTIFS('Резиденты — лонг-лист'!$Q$5:$Q$204,"C",'Резиденты — лонг-лист'!$D$5:$D$204,"Москва",'Резиденты — лонг-лист'!$S$5:$S$204,"Оплачен")+COUNTIFS('Резиденты — лонг-лист'!$Q$5:$Q$204,"C",'Резиденты — лонг-лист'!$D$5:$D$204,"Комбо (1+2)",'Резиденты — лонг-лист'!$S$5:$S$204,"Подписан")+COUNTIFS('Резиденты — лонг-лист'!$Q$5:$Q$204,"C",'Резиденты — лонг-лист'!$D$5:$D$204,"Комбо (1+2)",'Резиденты — лонг-лист'!$S$5:$S$204,"Оплачен") -> 0 | E23: =IF(C23=0,"",D23/C23) -> 0 | F23: =K15 -> 11 | G23: =COUNTIFS('Резиденты — лонг-лист'!$Q$5:$Q$204,"C",'Резиденты — лонг-лист'!$D$5:$D$204,"Санкт-Петербург",'Резиденты — лонг-лист'!$S$5:$S$204,"Подписан")+COUNTIFS('Резиденты — лонг-лист'!$Q$5:$Q$204,"C",'Резиденты — лонг-лист'!$D$5:$D$204,"Санкт-Петербург",'Резиденты — лонг-лист'!$S$5:$S$204,"Оплачен")+COUNTIFS('Резиденты — лонг-лист'!$Q$5:$Q$204,"C",'Резиденты — лонг-лист'!$D$5:$D$204,"Комбо (1+2)",'Резиденты — лонг-лист'!$S$5:$S$204,"Подписан")+COUNTIFS('Резиденты — лонг-лист'!$Q$5:$Q$204,"C",'Резиденты — лонг-лист'!$D$5:$D$204,"Комбо (1+2)",'Резиденты — лонг-лист'!$S$5:$S$204,"Оплачен") -> 0 | H23: =IF(F23=0,"",G23/F23) -> 0 | I23: =COUNTIFS('Резиденты — лонг-лист'!$Q$5:$Q$204,"C",'Резиденты — лонг-лист'!$S$5:$S$204,"Переговоры")+COUNTIFS('Резиденты — лонг-лист'!$Q$5:$Q$204,"C",'Резиденты — лонг-лист'!$S$5:$S$204,"КП отправлено") -> 0 | J23: =SUMIFS('Резиденты — лонг-лист'!$U$5:$U$204,'Резиденты — лонг-лист'!$Q$5:$Q$204,"C",'Резиденты — лонг-лист'!$S$5:$S$204,"Подписан")+SUMIFS('Резиденты — лонг-лист'!$U$5:$U$204,'Резиденты — лонг-лист'!$Q$5:$Q$204,"C",'Резиденты — лонг-лист'!$S$5:$S$204,"Оплачен") -> 0 | K23: =COUNTIFS('Резиденты — лонг-лист'!$Q$5:$Q$204,"C",'Резиденты — лонг-лист'!$S$5:$S$204,"Отказ") -> 0
B24: ИТОГО | C24: =SUM(C21:C23) -> 37 | D24: =SUM(D21:D23) -> 0 | E24: =IF(C24=0,"",D24/C24) -> 0 | F24: =SUM(F21:F23) -> 32 | G24: =SUM(G21:G23) -> 0 | H24: =IF(F24=0,"",G24/F24) -> 0 | I24: =SUM(I21:I23) -> 1 | J24: =SUM(J21:J23) -> 0 | K24: =SUM(K21:K23) -> 0
B25: Выручка — по ценам пакетов из матрицы 2027 (без допопций и % от выручки).
B27: 3. Карта категорий кухни — чтобы не было дублей и пустот
B28: Категория | C28: Мск цель | D28: Мск факт | E28: Мск разрыв | F28: СПб цель | G28: СПб факт | H28: СПб разрыв
B29: Бургеры / стритфуд | C29: 3 | D29: =COUNTIFS('Резиденты — лонг-лист'!$E$5:$E$204,$B29,'Резиденты — лонг-лист'!$D$5:$D$204,"Москва",'Резиденты — лонг-лист'!$S$5:$S$204,"Подписан")+COUNTIFS('Резиденты — лонг-лист'!$E$5:$E$204,$B29,'Резиденты — лонг-лист'!$D$5:$D$204,"Москва",'Резиденты — лонг-лист'!$S$5:$S$204,"Оплачен")+COUNTIFS('Резиденты — лонг-лист'!$E$5:$E$204,$B29,'Резиденты — лонг-лист'!$D$5:$D$204,"Комбо (1+2)",'Резиденты — лонг-лист'!$S$5:$S$204,"Подписан")+COUNTIFS('Резиденты — лонг-лист'!$E$5:$E$204,$B29,'Резиденты — лонг-лист'!$D$5:$D$204,"Комбо (1+2)",'Резиденты — лонг-лист'!$S$5:$S$204,"Оплачен") -> 0 | E29: =D29-C29 -> -3 | F29: 3 | G29: =COUNTIFS('Резиденты — лонг-лист'!$E$5:$E$204,$B29,'Резиденты — лонг-лист'!$D$5:$D$204,"Санкт-Петербург",'Резиденты — лонг-лист'!$S$5:$S$204,"Подписан")+COUNTIFS('Резиденты — лонг-лист'!$E$5:$E$204,$B29,'Резиденты — лонг-лист'!$D$5:$D$204,"Санкт-Петербург",'Резиденты — лонг-лист'!$S$5:$S$204,"Оплачен")+COUNTIFS('Резиденты — лонг-лист'!$E$5:$E$204,$B29,'Резиденты — лонг-лист'!$D$5:$D$204,"Комбо (1+2)",'Резиденты — лонг-лист'!$S$5:$S$204,"Подписан")+COUNTIFS('Резиденты — лонг-лист'!$E$5:$E$204,$B29,'Резиденты — лонг-лист'!$D$5:$D$204,"Комбо (1+2)",'Резиденты — лонг-лист'!$S$5:$S$204,"Оплачен") -> 0 | H29: =G29-F29 -> -3
B30: Азиатская | C30: 4 | D30: =COUNTIFS('Резиденты — лонг-лист'!$E$5:$E$204,$B30,'Резиденты — лонг-лист'!$D$5:$D$204,"Москва",'Резиденты — лонг-лист'!$S$5:$S$204,"Подписан")+COUNTIFS('Резиденты — лонг-лист'!$E$5:$E$204,$B30,'Резиденты — лонг-лист'!$D$5:$D$204,"Москва",'Резиденты — лонг-лист'!$S$5:$S$204,"Оплачен")+COUNTIFS('Резиденты — лонг-лист'!$E$5:$E$204,$B30,'Резиденты — лонг-лист'!$D$5:$D$204,"Комбо (1+2)",'Резиденты — лонг-лист'!$S$5:$S$204,"Подписан")+COUNTIFS('Резиденты — лонг-лист'!$E$5:$E$204,$B30,'Резиденты — лонг-лист'!$D$5:$D$204,"Комбо (1+2)",'Резиденты — лонг-лист'!$S$5:$S$204,"Оплачен") -> 0 | E30: =D30-C30 -> -4 | F30: 3 | G30: =COUNTIFS('Резиденты — лонг-лист'!$E$5:$E$204,$B30,'Резиденты — лонг-лист'!$D$5:$D$204,"Санкт-Петербург",'Резиденты — лонг-лист'!$S$5:$S$204,"Подписан")+COUNTIFS('Резиденты — лонг-лист'!$E$5:$E$204,$B30,'Резиденты — лонг-лист'!$D$5:$D$204,"Санкт-Петербург",'Резиденты — лонг-лист'!$S$5:$S$204,"Оплачен")+COUNTIFS('Резиденты — лонг-лист'!$E$5:$E$204,$B30,'Резиденты — лонг-лист'!$D$5:$D$204,"Комбо (1+2)",'Резиденты — лонг-лист'!$S$5:$S$204,"Подписан")+COUNTIFS('Резиденты — лонг-лист'!$E$5:$E$204,$B30,'Резиденты — лонг-лист'!$D$5:$D$204,"Комбо (1+2)",'Резиденты — лонг-лист'!$S$5:$S$204,"Оплачен") -> 0 | H30: =G30-F30 -> -3
B31: Кавказская | C31: 2 | D31: =COUNTIFS('Резиденты — лонг-лист'!$E$5:$E$204,$B31,'Резиденты — лонг-лист'!$D$5:$D$204,"Москва",'Резиденты — лонг-лист'!$S$5:$S$204,"Подписан")+COUNTIFS('Резиденты — лонг-лист'!$E$5:$E$204,$B31,'Резиденты — лонг-лист'!$D$5:$D$204,"Москва",'Резиденты — лонг-лист'!$S$5:$S$204,"Оплачен")+COUNTIFS('Резиденты — лонг-лист'!$E$5:$E$204,$B31,'Резиденты — лонг-лист'!$D$5:$D$204,"Комбо (1+2)",'Резиденты — лонг-лист'!$S$5:$S$204,"Подписан")+COUNTIFS('Резиденты — лонг-лист'!$E$5:$E$204,$B31,'Резиденты — лонг-лист'!$D$5:$D$204,"Комбо (1+2)",'Резиденты — лонг-лист'!$S$5:$S$204,"Оплачен") -> 0 | E31: =D31-C31 -> -2 | F31: 2 | G31: =COUNTIFS('Резиденты — лонг-лист'!$E$5:$E$204,$B31,'Резиденты — лонг-лист'!$D$5:$D$204,"Санкт-Петербург",'Резиденты — лонг-лист'!$S$5:$S$204,"Подписан")+COUNTIFS('Резиденты — лонг-лист'!$E$5:$E$204,$B31,'Резиденты — лонг-лист'!$D$5:$D$204,"Санкт-Петербург",'Резиденты — лонг-лист'!$S$5:$S$204,"Оплачен")+COUNTIFS('Резиденты — лонг-лист'!$E$5:$E$204,$B31,'Резиденты — лонг-лист'!$D$5:$D$204,"Комбо (1+2)",'Резиденты — лонг-лист'!$S$5:$S$204,"Подписан")+COUNTIFS('Резиденты — лонг-лист'!$E$5:$E$204,$B31,'Резиденты — лонг-лист'!$D$5:$D$204,"Комбо (1+2)",'Резиденты — лонг-лист'!$S$5:$S$204,"Оплачен") -> 0 | H31: =G31-F31 -> -2
B32: Итальянская / Европа | C32: 3 | D32: =COUNTIFS('Резиденты — лонг-лист'!$E$5:$E$204,$B32,'Резиденты — лонг-лист'!$D$5:$D$204,"Москва",'Резиденты — лонг-лист'!$S$5:$S$204,"Подписан")+COUNTIFS('Резиденты — лонг-лист'!$E$5:$E$204,$B32,'Резиденты — лонг-лист'!$D$5:$D$204,"Москва",'Резиденты — лонг-лист'!$S$5:$S$204,"Оплачен")+COUNTIFS('Резиденты — лонг-лист'!$E$5:$E$204,$B32,'Резиденты — лонг-лист'!$D$5:$D$204,"Комбо (1+2)",'Резиденты — лонг-лист'!$S$5:$S$204,"Подписан")+COUNTIFS('Резиденты — лонг-лист'!$E$5:$E$204,$B32,'Резиденты — лонг-лист'!$D$5:$D$204,"Комбо (1+2)",'Резиденты — лонг-лист'!$S$5:$S$204,"Оплачен") -> 0 | E32: =D32-C32 -> -3 | F32: 2 | G32: =COUNTIFS('Резиденты — лонг-лист'!$E$5:$E$204,$B32,'Резиденты — лонг-лист'!$D$5:$D$204,"Санкт-Петербург",'Резиденты — лонг-лист'!$S$5:$S$204,"Подписан")+COUNTIFS('Резиденты — лонг-лист'!$E$5:$E$204,$B32,'Резиденты — лонг-лист'!$D$5:$D$204,"Санкт-Петербург",'Резиденты — лонг-лист'!$S$5:$S$204,"Оплачен")+COUNTIFS('Резиденты — лонг-лист'!$E$5:$E$204,$B32,'Резиденты — лонг-лист'!$D$5:$D$204,"Комбо (1+2)",'Резиденты — лонг-лист'!$S$5:$S$204,"Подписан")+COUNTIFS('Резиденты — лонг-лист'!$E$5:$E$204,$B32,'Резиденты — лонг-лист'!$D$5:$D$204,"Комбо (1+2)",'Резиденты — лонг-лист'!$S$5:$S$204,"Оплачен") -> 0 | H32: =G32-F32 -> -2
B33: Мясо / гриль / BBQ | C33: 3 | D33: =COUNTIFS('Резиденты — лонг-лист'!$E$5:$E$204,$B33,'Резиденты — лонг-лист'!$D$5:$D$204,"Москва",'Резиденты — лонг-лист'!$S$5:$S$204,"Подписан")+COUNTIFS('Резиденты — лонг-лист'!$E$5:$E$204,$B33,'Резиденты — лонг-лист'!$D$5:$D$204,"Москва",'Резиденты — лонг-лист'!$S$5:$S$204,"Оплачен")+COUNTIFS('Резиденты — лонг-лист'!$E$5:$E$204,$B33,'Резиденты — лонг-лист'!$D$5:$D$204,"Комбо (1+2)",'Резиденты — лонг-лист'!$S$5:$S$204,"Подписан")+COUNTIFS('Резиденты — лонг-лист'!$E$5:$E$204,$B33,'Резиденты — лонг-лист'!$D$5:$D$204,"Комбо (1+2)",'Резиденты — лонг-лист'!$S$5:$S$204,"Оплачен") -> 0 | E33: =D33-C33 -> -3 | F33: 3 | G33: =COUNTIFS('Резиденты — лонг-лист'!$E$5:$E$204,$B33,'Резиденты — лонг-лист'!$D$5:$D$204,"Санкт-Петербург",'Резиденты — лонг-лист'!$S$5:$S$204,"Подписан")+COUNTIFS('Резиденты — лонг-лист'!$E$5:$E$204,$B33,'Резиденты — лонг-лист'!$D$5:$D$204,"Санкт-Петербург",'Резиденты — лонг-лист'!$S$5:$S$204,"Оплачен")+COUNTIFS('Резиденты — лонг-лист'!$E$5:$E$204,$B33,'Резиденты — лонг-лист'!$D$5:$D$204,"Комбо (1+2)",'Резиденты — лонг-лист'!$S$5:$S$204,"Подписан")+COUNTIFS('Резиденты — лонг-лист'!$E$5:$E$204,$B33,'Резиденты — лонг-лист'!$D$5:$D$204,"Комбо (1+2)",'Резиденты — лонг-лист'!$S$5:$S$204,"Оплачен") -> 0 | H33: =G33-F33 -> -3
B34: Морепродукты | C34: 2 | D34: =COUNTIFS('Резиденты — лонг-лист'!$E$5:$E$204,$B34,'Резиденты — лонг-лист'!$D$5:$D$204,"Москва",'Резиденты — лонг-лист'!$S$5:$S$204,"Подписан")+COUNTIFS('Резиденты — лонг-лист'!$E$5:$E$204,$B34,'Резиденты — лонг-лист'!$D$5:$D$204,"Москва",'Резиденты — лонг-лист'!$S$5:$S$204,"Оплачен")+COUNTIFS('Резиденты — лонг-лист'!$E$5:$E$204,$B34,'Резиденты — лонг-лист'!$D$5:$D$204,"Комбо (1+2)",'Резиденты — лонг-лист'!$S$5:$S$204,"Подписан")+COUNTIFS('Резиденты — лонг-лист'!$E$5:$E$204,$B34,'Резиденты — лонг-лист'!$D$5:$D$204,"Комбо (1+2)",'Резиденты — лонг-лист'!$S$5:$S$204,"Оплачен") -> 0 | E34: =D34-C34 -> -2 | F34: 2 | G34: =COUNTIFS('Резиденты — лонг-лист'!$E$5:$E$204,$B34,'Резиденты — лонг-лист'!$D$5:$D$204,"Санкт-Петербург",'Резиденты — лонг-лист'!$S$5:$S$204,"Подписан")+COUNTIFS('Резиденты — лонг-лист'!$E$5:$E$204,$B34,'Резиденты — лонг-лист'!$D$5:$D$204,"Санкт-Петербург",'Резиденты — лонг-лист'!$S$5:$S$204,"Оплачен")+COUNTIFS('Резиденты — лонг-лист'!$E$5:$E$204,$B34,'Резиденты — лонг-лист'!$D$5:$D$204,"Комбо (1+2)",'Резиденты — лонг-лист'!$S$5:$S$204,"Подписан")+COUNTIFS('Резиденты — лонг-лист'!$E$5:$E$204,$B34,'Резиденты — лонг-лист'!$D$5:$D$204,"Комбо (1+2)",'Резиденты — лонг-лист'!$S$5:$S$204,"Оплачен") -> 0 | H34: =G34-F34 -> -2
B35: Здоровая / веган | C35: 2 | D35: =COUNTIFS('Резиденты — лонг-лист'!$E$5:$E$204,$B35,'Резиденты — лонг-лист'!$D$5:$D$204,"Москва",'Резиденты — лонг-лист'!$S$5:$S$204,"Подписан")+COUNTIFS('Резиденты — лонг-лист'!$E$5:$E$204,$B35,'Резиденты — лонг-лист'!$D$5:$D$204,"Москва",'Резиденты — лонг-лист'!$S$5:$S$204,"Оплачен")+COUNTIFS('Резиденты — лонг-лист'!$E$5:$E$204,$B35,'Резиденты — лонг-лист'!$D$5:$D$204,"Комбо (1+2)",'Резиденты — лонг-лист'!$S$5:$S$204,"Подписан")+COUNTIFS('Резиденты — лонг-лист'!$E$5:$E$204,$B35,'Резиденты — лонг-лист'!$D$5:$D$204,"Комбо (1+2)",'Резиденты — лонг-лист'!$S$5:$S$204,"Оплачен") -> 0 | E35: =D35-C35 -> -2 | F35: 2 | G35: =COUNTIFS('Резиденты — лонг-лист'!$E$5:$E$204,$B35,'Резиденты — лонг-лист'!$D$5:$D$204,"Санкт-Петербург",'Резиденты — лонг-лист'!$S$5:$S$204,"Подписан")+COUNTIFS('Резиденты — лонг-лист'!$E$5:$E$204,$B35,'Резиденты — лонг-лист'!$D$5:$D$204,"Санкт-Петербург",'Резиденты — лонг-лист'!$S$5:$S$204,"Оплачен")+COUNTIFS('Резиденты — лонг-лист'!$E$5:$E$204,$B35,'Резиденты — лонг-лист'!$D$5:$D$204,"Комбо (1+2)",'Резиденты — лонг-лист'!$S$5:$S$204,"Подписан")+COUNTIFS('Резиденты — лонг-лист'!$E$5:$E$204,$B35,'Резиденты — лонг-лист'!$D$5:$D$204,"Комбо (1+2)",'Резиденты — лонг-лист'!$S$5:$S$204,"Оплачен") -> 0 | H35: =G35-F35 -> -2
B36: Десерты / выпечка | C36: 3 | D36: =COUNTIFS('Резиденты — лонг-лист'!$E$5:$E$204,$B36,'Резиденты — лонг-лист'!$D$5:$D$204,"Москва",'Резиденты — лонг-лист'!$S$5:$S$204,"Подписан")+COUNTIFS('Резиденты — лонг-лист'!$E$5:$E$204,$B36,'Резиденты — лонг-лист'!$D$5:$D$204,"Москва",'Резиденты — лонг-лист'!$S$5:$S$204,"Оплачен")+COUNTIFS('Резиденты — лонг-лист'!$E$5:$E$204,$B36,'Резиденты — лонг-лист'!$D$5:$D$204,"Комбо (1+2)",'Резиденты — лонг-лист'!$S$5:$S$204,"Подписан")+COUNTIFS('Резиденты — лонг-лист'!$E$5:$E$204,$B36,'Резиденты — лонг-лист'!$D$5:$D$204,"Комбо (1+2)",'Резиденты — лонг-лист'!$S$5:$S$204,"Оплачен") -> 0 | E36: =D36-C36 -> -3 | F36: 3 | G36: =COUNTIFS('Резиденты — лонг-лист'!$E$5:$E$204,$B36,'Резиденты — лонг-лист'!$D$5:$D$204,"Санкт-Петербург",'Резиденты — лонг-лист'!$S$5:$S$204,"Подписан")+COUNTIFS('Резиденты — лонг-лист'!$E$5:$E$204,$B36,'Резиденты — лонг-лист'!$D$5:$D$204,"Санкт-Петербург",'Резиденты — лонг-лист'!$S$5:$S$204,"Оплачен")+COUNTIFS('Резиденты — лонг-лист'!$E$5:$E$204,$B36,'Резиденты — лонг-лист'!$D$5:$D$204,"Комбо (1+2)",'Резиденты — лонг-лист'!$S$5:$S$204,"Подписан")+COUNTIFS('Резиденты — лонг-лист'!$E$5:$E$204,$B36,'Резиденты — лонг-лист'!$D$5:$D$204,"Комбо (1+2)",'Резиденты — лонг-лист'!$S$5:$S$204,"Оплачен") -> 0 | H36: =G36-F36 -> -3
B37: Кофе | C37: 3 | D37: =COUNTIFS('Резиденты — лонг-лист'!$E$5:$E$204,$B37,'Резиденты — лонг-лист'!$D$5:$D$204,"Москва",'Резиденты — лонг-лист'!$S$5:$S$204,"Подписан")+COUNTIFS('Резиденты — лонг-лист'!$E$5:$E$204,$B37,'Резиденты — лонг-лист'!$D$5:$D$204,"Москва",'Резиденты — лонг-лист'!$S$5:$S$204,"Оплачен")+COUNTIFS('Резиденты — лонг-лист'!$E$5:$E$204,$B37,'Резиденты — лонг-лист'!$D$5:$D$204,"Комбо (1+2)",'Резиденты — лонг-лист'!$S$5:$S$204,"Подписан")+COUNTIFS('Резиденты — лонг-лист'!$E$5:$E$204,$B37,'Резиденты — лонг-лист'!$D$5:$D$204,"Комбо (1+2)",'Резиденты — лонг-лист'!$S$5:$S$204,"Оплачен") -> 0 | E37: =D37-C37 -> -3 | F37: 2 | G37: =COUNTIFS('Резиденты — лонг-лист'!$E$5:$E$204,$B37,'Резиденты — лонг-лист'!$D$5:$D$204,"Санкт-Петербург",'Резиденты — лонг-лист'!$S$5:$S$204,"Подписан")+COUNTIFS('Резиденты — лонг-лист'!$E$5:$E$204,$B37,'Резиденты — лонг-лист'!$D$5:$D$204,"Санкт-Петербург",'Резиденты — лонг-лист'!$S$5:$S$204,"Оплачен")+COUNTIFS('Резиденты — лонг-лист'!$E$5:$E$204,$B37,'Резиденты — лонг-лист'!$D$5:$D$204,"Комбо (1+2)",'Резиденты — лонг-лист'!$S$5:$S$204,"Подписан")+COUNTIFS('Резиденты — лонг-лист'!$E$5:$E$204,$B37,'Резиденты — лонг-лист'!$D$5:$D$204,"Комбо (1+2)",'Резиденты — лонг-лист'!$S$5:$S$204,"Оплачен") -> 0 | H37: =G37-F37 -> -2
B38: Безалкогольные напитки | C38: 3 | D38: =COUNTIFS('Резиденты — лонг-лист'!$E$5:$E$204,$B38,'Резиденты — лонг-лист'!$D$5:$D$204,"Москва",'Резиденты — лонг-лист'!$S$5:$S$204,"Подписан")+COUNTIFS('Резиденты — лонг-лист'!$E$5:$E$204,$B38,'Резиденты — лонг-лист'!$D$5:$D$204,"Москва",'Резиденты — лонг-лист'!$S$5:$S$204,"Оплачен")+COUNTIFS('Резиденты — лонг-лист'!$E$5:$E$204,$B38,'Резиденты — лонг-лист'!$D$5:$D$204,"Комбо (1+2)",'Резиденты — лонг-лист'!$S$5:$S$204,"Подписан")+COUNTIFS('Резиденты — лонг-лист'!$E$5:$E$204,$B38,'Резиденты — лонг-лист'!$D$5:$D$204,"Комбо (1+2)",'Резиденты — лонг-лист'!$S$5:$S$204,"Оплачен") -> 0 | E38: =D38-C38 -> -3 | F38: 2 | G38: =COUNTIFS('Резиденты — лонг-лист'!$E$5:$E$204,$B38,'Резиденты — лонг-лист'!$D$5:$D$204,"Санкт-Петербург",'Резиденты — лонг-лист'!$S$5:$S$204,"Подписан")+COUNTIFS('Резиденты — лонг-лист'!$E$5:$E$204,$B38,'Резиденты — лонг-лист'!$D$5:$D$204,"Санкт-Петербург",'Резиденты — лонг-лист'!$S$5:$S$204,"Оплачен")+COUNTIFS('Резиденты — лонг-лист'!$E$5:$E$204,$B38,'Резиденты — лонг-лист'!$D$5:$D$204,"Комбо (1+2)",'Резиденты — лонг-лист'!$S$5:$S$204,"Подписан")+COUNTIFS('Резиденты — лонг-лист'!$E$5:$E$204,$B38,'Резиденты — лонг-лист'!$D$5:$D$204,"Комбо (1+2)",'Резиденты — лонг-лист'!$S$5:$S$204,"Оплачен") -> 0 | H38: =G38-F38 -> -2
B39: Бар / алкоголь | C39: 2 | D39: =COUNTIFS('Резиденты — лонг-лист'!$E$5:$E$204,$B39,'Резиденты — лонг-лист'!$D$5:$D$204,"Москва",'Резиденты — лонг-лист'!$S$5:$S$204,"Подписан")+COUNTIFS('Резиденты — лонг-лист'!$E$5:$E$204,$B39,'Резиденты — лонг-лист'!$D$5:$D$204,"Москва",'Резиденты — лонг-лист'!$S$5:$S$204,"Оплачен")+COUNTIFS('Резиденты — лонг-лист'!$E$5:$E$204,$B39,'Резиденты — лонг-лист'!$D$5:$D$204,"Комбо (1+2)",'Резиденты — лонг-лист'!$S$5:$S$204,"Подписан")+COUNTIFS('Резиденты — лонг-лист'!$E$5:$E$204,$B39,'Резиденты — лонг-лист'!$D$5:$D$204,"Комбо (1+2)",'Резиденты — лонг-лист'!$S$5:$S$204,"Оплачен") -> 0 | E39: =D39-C39 -> -2 | F39: 2 | G39: =COUNTIFS('Резиденты — лонг-лист'!$E$5:$E$204,$B39,'Резиденты — лонг-лист'!$D$5:$D$204,"Санкт-Петербург",'Резиденты — лонг-лист'!$S$5:$S$204,"Подписан")+COUNTIFS('Резиденты — лонг-лист'!$E$5:$E$204,$B39,'Резиденты — лонг-лист'!$D$5:$D$204,"Санкт-Петербург",'Резиденты — лонг-лист'!$S$5:$S$204,"Оплачен")+COUNTIFS('Резиденты — лонг-лист'!$E$5:$E$204,$B39,'Резиденты — лонг-лист'!$D$5:$D$204,"Комбо (1+2)",'Резиденты — лонг-лист'!$S$5:$S$204,"Подписан")+COUNTIFS('Резиденты — лонг-лист'!$E$5:$E$204,$B39,'Резиденты — лонг-лист'!$D$5:$D$204,"Комбо (1+2)",'Резиденты — лонг-лист'!$S$5:$S$204,"Оплачен") -> 0 | H39: =G39-F39 -> -2
B40: Фермерские продукты | C40: 5 | D40: =COUNTIFS('Резиденты — лонг-лист'!$E$5:$E$204,$B40,'Резиденты — лонг-лист'!$D$5:$D$204,"Москва",'Резиденты — лонг-лист'!$S$5:$S$204,"Подписан")+COUNTIFS('Резиденты — лонг-лист'!$E$5:$E$204,$B40,'Резиденты — лонг-лист'!$D$5:$D$204,"Москва",'Резиденты — лонг-лист'!$S$5:$S$204,"Оплачен")+COUNTIFS('Резиденты — лонг-лист'!$E$5:$E$204,$B40,'Резиденты — лонг-лист'!$D$5:$D$204,"Комбо (1+2)",'Резиденты — лонг-лист'!$S$5:$S$204,"Подписан")+COUNTIFS('Резиденты — лонг-лист'!$E$5:$E$204,$B40,'Резиденты — лонг-лист'!$D$5:$D$204,"Комбо (1+2)",'Резиденты — лонг-лист'!$S$5:$S$204,"Оплачен") -> 0 | E40: =D40-C40 -> -5 | F40: 4 | G40: =COUNTIFS('Резиденты — лонг-лист'!$E$5:$E$204,$B40,'Резиденты — лонг-лист'!$D$5:$D$204,"Санкт-Петербург",'Резиденты — лонг-лист'!$S$5:$S$204,"Подписан")+COUNTIFS('Резиденты — лонг-лист'!$E$5:$E$204,$B40,'Резиденты — лонг-лист'!$D$5:$D$204,"Санкт-Петербург",'Резиденты — лонг-лист'!$S$5:$S$204,"Оплачен")+COUNTIFS('Резиденты — лонг-лист'!$E$5:$E$204,$B40,'Резиденты — лонг-лист'!$D$5:$D$204,"Комбо (1+2)",'Резиденты — лонг-лист'!$S$5:$S$204,"Подписан")+COUNTIFS('Резиденты — лонг-лист'!$E$5:$E$204,$B40,'Резиденты — лонг-лист'!$D$5:$D$204,"Комбо (1+2)",'Резиденты — лонг-лист'!$S$5:$S$204,"Оплачен") -> 0 | H40: =G40-F40 -> -4
... B42: Другое | C42: 0 | D42: =COUNTIFS('Резиденты — лонг-лист'!$E$5:$E$204,$B42,'Резиденты — лонг-лист'!$D$5:$D$204,"Москва",'Резиденты — лонг-лист'!$S$5:$S$204,"Подписан")+COUNTIFS('Резиденты — лонг-лист'!$E$5:$E$204,$B42,'Резиденты — лонг-лист'!$D$5:$D$204,"Москва",'Резиденты — лонг-лист'!$S$5:$S$204,"Оплачен")+COUNTIFS('Резиденты — лонг-лист'!$E$5:$E$204,$B42,'Резиденты — лонг-лист'!$D$5:$D$204,"Комбо (1+2)",'Резиденты — лонг-лист'!$S$5:$S$204,"Подписан")+COUNTIFS('Резиденты — лонг-лист'!$E$5:$E$204,$B42,'Резиденты — лонг-лист'!$D$5:$D$204,"Комбо (1+2)",'Резиденты — лонг-лист'!$S$5:$S$204,"Оплачен") -> 0 | E42: =D42-C42 -> 0 | F42: 0 | G42: =COUNTIFS('Резиденты — лонг-лист'!$E$5:$E$204,$B42,'Резиденты — лонг-лист'!$D$5:$D$204,"Санкт-Петербург",'Резиденты — лонг-лист'!$S$5:$S$204,"Подписан")+COUNTIFS('Резиденты — лонг-лист'!$E$5:$E$204,$B42,'Резиденты — лонг-лист'!$D$5:$D$204,"Санкт-Петербург",'Резиденты — лонг-лист'!$S$5:$S$204,"Оплачен")+COUNTIFS('Резиденты — лонг-лист'!$E$5:$E$204,$B42,'Резиденты — лонг-лист'!$D$5:$D$204,"Комбо (1+2)",'Резиденты — лонг-лист'!$S$5:$S$204,"Подписан")+COUNTIFS('Резиденты — лонг-лист'!$E$5:$E$204,$B42,'Резиденты — лонг-лист'!$D$5:$D$204,"Комбо (1+2)",'Резиденты — лонг-лист'!$S$5:$S$204,"Оплачен") -> 0 | H42: =G42-F42 -> 0
B43: Разрыв < 0 (красный) — категория не закрыта, добирать. Разрыв > 0 (оранжевый) — перебор, риск каннибализации выручки.

Sheet Резиденты — лонг-лист
B1: Лонг-лист резидентов 2027
B2: Одна строка — один резидент. Заполняйте жёлтые колонки; балл, уровень и цена пакета считаются сами. Строка 5 — пример, удалите или замените.
B4: № | C4: Резидент | D4: Город | E4: Категория кухни | F4: Пакет | G4: Вариант (1=Ж, 2=Д) | H4: Узнаваемость | I4: Средний чек | J4: Выручка | K4: Медийность | L4: Надёжность | M4: Уникальность | N4: Балл | O4: Уровень (расчёт) | P4: Уровень (вручную) | Q4: Итоговый уровень | R4: Был в 2026 | S4: Статус | T4: Ответственный | U4: Цена пакета 2027 ₽ | V4: Комментарий
B5: =IF(C5="","",ROW()-4) -> 1 | C5: ПРИМЕР: Ресторан «Название» | D5: Москва | E5: Мясо / гриль / BBQ | F5: Корнер №4 | G5: 1 | H5: 5 | I5: 4 | J5: 4 | K5: 5 | L5: 4 | M5: 3 | N5: =IF(COUNT(H5:M5)<6,"",ROUND((H5*'Резиденты — уровни'!$C$19+I5*'Резиденты — уровни'!$C$20+J5*'Резиденты — уровни'!$C$21+K5*'Резиденты — уровни'!$C$22+L5*'Резиденты — уровни'!$C$23+M5*'Резиденты — уровни'!$C$24)/SUM('Резиденты — уровни'!$C$19:$C$24),2)) -> 4.3 | O5: =IF(N5="","",IF(N5>='Резиденты — уровни'!$C$27,"A",IF(N5>='Резиденты — уровни'!$C$28,"B","C"))) -> A | Q5: =IF(P5<>"",P5,O5) -> A | R5: Да | S5: Переговоры | T5: Иванова | U5: =IF(OR(F5="",D5=""),"",IF(G5=2,SUMIFS('Матрица 2027'!$J$6:$J$53,'Матрица 2027'!$B$6:$B$53,F5,'Матрица 2027'!$C$6:$C$53,D5),SUMIFS('Матрица 2027'!$I$6:$I$53,'Матрица 2027'!$B$6:$B$53,F5,'Матрица 2027'!$C$6:$C$53,D5))) -> 310000 | V5: Хочет место у главной сцены
B6: =IF(C6="","",ROW()-4) | N6: =IF(COUNT(H6:M6)<6,"",ROUND((H6*'Резиденты — уровни'!$C$19+I6*'Резиденты — уровни'!$C$20+J6*'Резиденты — уровни'!$C$21+K6*'Резиденты — уровни'!$C$22+L6*'Резиденты — уровни'!$C$23+M6*'Резиденты — уровни'!$C$24)/SUM('Резиденты — уровни'!$C$19:$C$24),2)) | O6: =IF(N6="","",IF(N6>='Резиденты — уровни'!$C$27,"A",IF(N6>='Резиденты — уровни'!$C$28,"B","C"))) | Q6: =IF(P6<>"",P6,O6) | U6: =IF(OR(F6="",D6=""),"",IF(G6=2,SUMIFS('Матрица 2027'!$J$6:$J$53,'Матрица 2027'!$B$6:$B$53,F6,'Матрица 2027'!$C$6:$C$53,D6),SUMIFS('Матрица 2027'!$I$6:$I$53,'Матрица 2027'!$B$6:$B$53,F6,'Матрица 2027'!$C$6:$C$53,D6)))
