Workbook

Sheet Фудкорты 2027
B1: Фудкорты 2027: себестоимость, цена резиденту и маржа
B2: Жёлтые ячейки — ввод. Себестоимость и цены — из вкладки «Бюджет» (данные пользователя). Цена резиденту — с НДС.
B3: НДС | C3: 0.22
B5: Город | C5: Фудкорт | D5: Формат точки | E5: Точек | F5: С/с фудкорта, ₽ | G5: С/с на точку, ₽ | H5: Цена резиденту с НДС, ₽ | I5: Цена без НДС, ₽ | J5: Маржа на точку, ₽ | K5: Маржа фудкорта, ₽ | L5: Безубыток, точек | M5: Цена 2026, ₽ | N5: Комментарий
B6: Москва | C6: Основной (большой) | D6: корнер 3×3 | E6: 25 | F6: =4515279-1000000 -> 3515279 | G6: =IF(OR(F6="",E6=""),"",F6/E6) -> 140611.16 | H6: 200000 | I6: =IF(H6="","",H6/(1+$C$3)) -> 163934.43 | J6: =IF(OR(G6="",I6=""),"",I6-G6) -> 23323.266 | K6: =IF(J6="","",J6*E6) -> 583081.66 | L6: =IF(OR(F6="",I6=""),"",IF(CEILING(F6/I6,1)>E6,"не выходит",CEILING(F6/I6,1))) -> 22 | M6: 195–280 тыс (Корнер №1–4, железо) | N6: С/с 2026 на 33 точки (4,52 млн) минус ~1 млн экономии в 2027 — оценка пользователя
B7: Москва | C7: Основной, двойной корнер | D7: корнер 6×3 | E7: 1 | F7: =G6*2 -> 281222.32 | G7: =IF(OR(F7="",E7=""),"",F7/E7) -> 281222.32 | H7: 380000 | I7: =IF(H7="","",H7/(1+$C$3)) -> 311475.41 | J7: =IF(OR(G7="",I7=""),"",I7-G7) -> 30253.09 | K7: =IF(J7="","",J7*E7) -> 30253.09 | M7: 450–475 тыс | N7: 1 двойной = 2 места из 25
B8: Москва | C8: Купер (доставка + общий трафик) | D8: шатёр-кухня 5×5 | E8: 7 | G8: =IF(OR(F8="",E8=""),"",F8/E8) | H8: 200000 | I8: =IF(H8="","",H8/(1+$C$3)) -> 163934.43 | J8: =IF(OR(G8="",I8=""),"",I8-G8) | K8: =IF(J8="","",J8*E8) | M8: Dark Kitchen 390 тыс | N8: Нет расчёта себестоимости шатра-пагоды
B9: Москва | C9: 2-я сцена | D9: корнер | E9: 5 | G9: =IF(OR(F9="",E9=""),"",F9/E9) | I9: =IF(H9="","",H9/(1+$C$3)) | J9: =IF(OR(G9="",I9=""),"",I9-G9) | K9: =IF(J9="","",J9*E9) | N9: Нет себестоимости и цены
B10: Москва | C10: VIP | D10: корнер | E10: 4 | G10: =IF(OR(F10="",E10=""),"",F10/E10) | I10: =IF(H10="","",H10/(1+$C$3)) | J10: =IF(OR(G10="",I10=""),"",I10-G10) | K10: =IF(J10="","",J10*E10) | M10: ВИП-корнер 250 тыс | N10: Нет себестоимости и цены
B11: Москва | C11: Мороженое | D11: тележка | E11: 4 | G11: =IF(OR(F11="",E11=""),"",F11/E11) | I11: =IF(H11="","",H11/(1+$C$3)) | J11: =IF(OR(G11="",I11=""),"",I11-G11) | K11: =IF(J11="","",J11*E11) | M11: 75 тыс | N11: Нет себестоимости и цены
B12: Москва | C12: Деревянный ФК | D12: корнер 4,5×3 | E12: 10 | F12: 1930000 | G12: =IF(OR(F12="",E12=""),"",F12/E12) -> 193000 | H12: 280000 | I12: =IF(H12="","",H12/(1+$C$3)) -> 229508.2 | J12: =IF(OR(G12="",I12=""),"",I12-G12) -> 36508.197 | K12: =IF(J12="","",J12*E12) -> 365081.97 | L12: =IF(OR(F12="",I12=""),"",IF(CEILING(F12/I12,1)>E12,"не выходит",CEILING(F12/I12,1))) -> 9 | N12: Есть в «Бюджете», но нет в новом плане Москвы — оставить или убрать?
B13: Петербург | C13: Основной | D13: корнер 3×3 | E13: 15 | F13: 3839000 | G13: =IF(OR(F13="",E13=""),"",F13/E13) -> 255933.33 | H13: 170000 | I13: =IF(H13="","",H13/(1+$C$3)) -> 139344.26 | J13: =IF(OR(G13="",I13=""),"",I13-G13) -> -116589.07 | K13: =IF(J13="","",J13*E13) -> -1748836.1 | L13: =IF(OR(F13="",I13=""),"",IF(CEILING(F13/I13,1)>E13,"не выходит",CEILING(F13/I13,1))) -> не выходит | M13: 180–260 тыс (Корнер №1–4, железо) | N13: В «Бюджете» с/с делится на 33, а точек 15. Здесь — на 15
B14: Петербург | C14: Основной, двойной корнер | D14: корнер 6×3 | E14: 1 | F14: =G13*2 -> 511866.67 | G14: =IF(OR(F14="",E14=""),"",F14/E14) -> 511866.67 | H14: 320000 | I14: =IF(H14="","",H14/(1+$C$3)) -> 262295.08 | J14: =IF(OR(G14="",I14=""),"",I14-G14) -> -249571.58 | K14: =IF(J14="","",J14*E14) -> -249571.58 | M14: 410–435 тыс | N14: 1 двойной = 2 места из 15
B15: Петербург | C15: Деревянный ФК | D15: корнер 4,5×3 | E15: 15 | F15: 2401000 | G15: =IF(OR(F15="",E15=""),"",F15/E15) -> 160066.67 | H15: 230000 | I15: =IF(H15="","",H15/(1+$C$3)) -> 188524.59 | J15: =IF(OR(G15="",I15=""),"",I15-G15) -> 28457.923 | K15: =IF(J15="","",J15*E15) -> 426868.85 | L15: =IF(OR(F15="",I15=""),"",IF(CEILING(F15/I15,1)>E15,"не выходит",CEILING(F15/I15,1))) -> 13 | M15: 160–220 тыс (дерево 3×3)
B17: Итого Москва (основной + дерево) | K17: =K6+K12 -> 948163.62
B18: Итого Петербург (основной + дерево) | K18: =K13+K15 -> -1321967.2
B19: Маржа фудкорта считается при продаже всех точек. Безубыток — сколько точек нужно продать, чтобы покрыть с/с фудкорта.
B21: Проверка для резидента: окупит ли он пакет
B22: Цена пакета, ₽ | C22: =H6 -> 200000
B23: Средний чек, ₽ | C23: 800 | D23: Допущение — замените фактическим средним чеком 2026
B24: Доля пакета в выручке резидента (ориентир) | C24: 0.15 | D24: Ориентир, не норма: при доле выше ~20% резидент обычно уходит в минус после продуктов и персонала
B25: Нужная выручка резидента за фестиваль, ₽ | C25: =C22/C24 -> 1333333.3
B26: Нужно чеков за фестиваль | C26: =C25/C23 -> 1666.6667

Sheet План продаж
B1: План продаж 2027 — вал по пакетам
B2: Жёлтое — ввод. Зелёное — ссылка на лист «Фудкорты 2027». Цены с НДС.
B4: Город | C4: Пакет | D4: Ед. | E4: Кол-во | F4: Цена с НДС, ₽ | G4: Вал с НДС, ₽ | H4: Вал без НДС, ₽ | I4: С/с, ₽ | J4: Маржа, ₽ | K4: Комментарий
B5: Москва | C5: Основной фудкорт, корнер 3×3 | D5: точка | E5: ='Фудкорты 2027'!E6 -> 25 | F5: ='Фудкорты 2027'!H6 -> 200000 | G5: =IF(OR(E5="",F5=""),0,E5*F5) -> 5000000 | H5: =G5/(1+'Фудкорты 2027'!$C$3) -> 4098360.7 | I5: ='Фудкорты 2027'!F6 -> 3515279 | J5: =IF(I5="","",H5-I5) -> 583081.66
B6: Москва | C6: Фудкорт Купер, шатёр-кухня 5×5 | D6: точка | E6: 7 | F6: ='Фудкорты 2027'!H8 -> 200000 | G6: =IF(OR(E6="",F6=""),0,E6*F6) -> 1400000 | H6: =G6/(1+'Фудкорты 2027'!$C$3) -> 1147541 | J6: =IF(I6="","",H6-I6) | K6: Два потока: доставка + трафик. Нет с/с шатра
B7: Москва | C7: Фудкорт 2-й сцены, корнер | D7: точка | E7: 5 | F7: 200000 | G7: =IF(OR(E7="",F7=""),0,E7*F7) -> 1000000 | H7: =G7/(1+'Фудкорты 2027'!$C$3) -> 819672.13 | J7: =IF(I7="","",H7-I7) | K7: Цена — допущение (как корнер 3×3). Нет с/с
B8: Москва | C8: Деревянный фудкорт, корнер 4,5×3 | D8: точка | E8: ='Фудкорты 2027'!E12 -> 10 | F8: ='Фудкорты 2027'!H12 -> 280000 | G8: =IF(OR(E8="",F8=""),0,E8*F8) -> 2800000 | H8: =G8/(1+'Фудкорты 2027'!$C$3) -> 2295082 | I8: ='Фудкорты 2027'!F12 -> 1930000 | J8: =IF(I8="","",H8-I8) -> 365081.97 | K8: Уточнить: входит ли в план 2027
B9: Москва | C9: Мороженое, пакет на 4 тележки | D9: пакет | E9: 1 | F9: 450000 | G9: =IF(OR(E9="",F9=""),0,E9*F9) -> 450000 | H9: =G9/(1+'Фудкорты 2027'!$C$3) -> 368852.46 | J9: =IF(I9="","",H9-I9)
B10: Петербург | C10: Основной фудкорт, корнер 3×3 | D10: точка | E10: ='Фудкорты 2027'!E13 -> 15 | F10: ='Фудкорты 2027'!H13 -> 170000 | G10: =IF(OR(E10="",F10=""),0,E10*F10) -> 2550000 | H10: =G10/(1+'Фудкорты 2027'!$C$3) -> 2090163.9 | I10: ='Фудкорты 2027'!F13 -> 3839000 | J10: =IF(I10="","",H10-I10) -> -1748836.1 | K10: С/с посчитана на 15 точек — проверить (в «Бюджете» ÷33)
B11: Петербург | C11: Деревянный фудкорт, корнер 4,5×3 | D11: точка | E11: ='Фудкорты 2027'!E15 -> 15 | F11: ='Фудкорты 2027'!H15 -> 230000 | G11: =IF(OR(E11="",F11=""),0,E11*F11) -> 3450000 | H11: =G11/(1+'Фудкорты 2027'!$C$3) -> 2827868.9 | I11: ='Фудкорты 2027'!F15 -> 2401000 | J11: =IF(I11="","",H11-I11) -> 426868.85
B12: Петербург | C12: Мороженое | D12: точка | E12: 3 | F12: 70000 | G12: =IF(OR(E12="",F12=""),0,E12*F12) -> 210000 | H12: =G12/(1+'Фудкорты 2027'!$C$3) -> 172131.15 | J12: =IF(I12="","",H12-I12)
B13: Мск + СПб | C13: VIP фудкорт — Smoke BBQ (4 точки Мск + 3 СПб) | D13: пакет | E13: 1 | F13: 1200000 | G13: =IF(OR(E13="",F13=""),0,E13*F13) -> 1200000 | H13: =G13/(1+'Фудкорты 2027'!$C$3) -> 983606.56 | J13: =IF(I13="","",H13-I13) | K13: Фикс. Альтернатива 60/40 — блок ниже
B14: Мск + СПб | C14: Бар — партнёр, 60/40 за вычетом с/с продукта | D14: % | G14: =IF(G23="",0,G23*(1+'Фудкорты 2027'!$C$3)) -> 0 | H14: =G14/(1+'Фудкорты 2027'!$C$3) -> 0 | J14: =IF(I14="","",H14-I14) | K14: Доход Афиши из блока 60/40 (ниже), пересчитан с НДС для сопоставимости
B15: ИТОГО | G15: =SUM(G5:G14) -> 18060000 | H15: =SUM(H5:H14) -> 14803279 | I15: =SUM(I5:I14) -> 11685279 | J15: =SUMIF(I5:I14,"<>",H5:H14)-SUM(I5:I14) -> -373803.59 | K15: Маржа — только по строкам, где есть с/с
B18: Модель 60/40: Афиша 60% / партнёр 40% от (выручка − с/с продукта)
C19: Показатель | F19: Smoke BBQ (VIP) | G19: Бар
C20: Прогноз выручки точки за оба фестиваля, ₽ | H20: Введите прогноз — без него доход не считается
C21: С/с продукта, % от выручки | F21: 0.35 | G21: 0.3 | H21: Допущение — уточнить по меню партнёра
C22: Доля Афиши | F22: 0.6 | G22: 0.6
C23: Доход Афиши, ₽ | F23: =IF(F20="","",F20*(1-F21)*F22) | G23: =IF(G20="","",G20*(1-G21)*G22)
C24: Фикс для сравнения, ₽ | F24: =F13 -> 1200000
C25: Выручка, при которой 60/40 = фикс, ₽ | F25: =F24/((1-F21)*F22) -> 3076923.1
B28: Комбо Москва + Петербург
B29: Скидка ранней волны (до 31 января) | F29: 0.1
B30: Скидка стандартного комбо (февраль–май) | F30: 0.05
B32: Волна | C32: Комбо | D32: Цена отдельно, ₽ | E32: План, шт | F32: Цена комбо, ₽ | G32: Мин. цена (с/с с НДС), ₽ | H32: Проверка | I32: Скидка всего, ₽
B33: Январь (ранняя) | C33: 2 железных: Мск 3×3 + СПб 3×3 | D33: ='Фудкорты 2027'!H6+'Фудкорты 2027'!H13 -> 370000 | E33: 8 | F33: =ROUND(D33*(1-$F$29)/5000,0)*5000 -> 335000 | G33: =('Фудкорты 2027'!G6+'Фудкорты 2027'!G13)*(1+'Фудкорты 2027'!$C$3) -> 483784.28 | H33: =IF(F33>=G33,"ок","ниже с/с") -> ниже с/с | I33: =(D33-F33)*E33 -> 280000
B34: Январь (ранняя) | C34: Дерево Мск + железо СПб | D34: ='Фудкорты 2027'!H12+'Фудкорты 2027'!H13 -> 450000 | E34: 3 | F34: =ROUND(D34*(1-$F$29)/5000,0)*5000 -> 405000 | G34: =('Фудкорты 2027'!G12+'Фудкорты 2027'!G13)*(1+'Фудкорты 2027'!$C$3) -> 547698.67 | H34: =IF(F34>=G34,"ок","ниже с/с") -> ниже с/с | I34: =(D34-F34)*E34 -> 135000
B35: Январь (ранняя) | C35: Железо Мск + дерево СПб | D35: ='Фудкорты 2027'!H6+'Фудкорты 2027'!H15 -> 430000 | E35: 3 | F35: =ROUND(D35*(1-$F$29)/5000,0)*5000 -> 385000 | G35: =('Фудкорты 2027'!G6+'Фудкорты 2027'!G15)*(1+'Фудкорты 2027'!$C$3) -> 366826.95 | H35: =IF(F35>=G35,"ок","ниже с/с") -> ок | I35: =(D35-F35)*E35 -> 135000
B36: Февраль–май | C36: 2 железных: Мск 3×3 + СПб 3×3 | D36: ='Фудкорты 2027'!H6+'Фудкорты 2027'!H13 -> 370000 | E36: 4 | F36: =ROUND(D36*(1-$F$30)/5000,0)*5000 -> 350000 | G36: =('Фудкорты 2027'!G6+'Фудкорты 2027'!G13)*(1+'Фудкорты 2027'!$C$3) -> 483784.28 | H36: =IF(F36>=G36,"ок","ниже с/с") -> ниже с/с | I36: =(D36-F36)*E36 -> 80000
B37: Февраль–май | C37: Дерево Мск + железо СПб | D37: ='Фудкорты 2027'!H12+'Фудкорты 2027'!H13 -> 450000 | E37: 2 | F37: =ROUND(D37*(1-$F$30)/5000,0)*5000 -> 430000 | G37: =('Фудкорты 2027'!G12+'Фудкорты 2027'!G13)*(1+'Фудкорты 2027'!$C$3) -> 547698.67 | H37: =IF(F37>=G37,"ок","ниже с/с") -> ниже с/с | I37: =(D37-F37)*E37 -> 40000
B38: Февраль–май | C38: Железо Мск + дерево СПб | D38: ='Фудкорты 2027'!H6+'Фудкорты 2027'!H15 -> 430000 | E38: 2 | F38: =ROUND(D38*(1-$F$30)/5000,0)*5000 -> 410000 | G38: =('Фудкорты 2027'!G6+'Фудкорты 2027'!G15)*(1+'Фудкорты 2027'!$C$3) -> 366826.95 | H38: =IF(F38>=G38,"ок","ниже с/с") -> ок | I38: =(D38-F38)*E38 -> 40000
B39: Скидки по комбо всего | I39: =SUM(I33:I38) -> 710000
B40: Вал с НДС с учётом скидок по комбо | I40: =G15-I39 -> 17350000
B41: Комбо занимают места из основных фудкортов: 1 комбо = 1 место в Москве + 1 в Петербурге. Штуки комбо — допущение, меняйте.
B42: «Ниже с/с» у комбо с железом СПб — из-за с/с СПб на 15 точек. Если точек 33, проверка станет «ок».
B45: Цель продаж по месяцам (накопительно)
B46: Месяц | E46: Доля вала | F46: Вал накопит., ₽
B47: Январь | E47: 0.3 | F47: =E47*$I$40 -> 5205000
B48: Февраль | E48: 0.5 | F48: =E48*$I$40 -> 8675000
...

Sheet Опции пакетов
B1: Что входит в каждый пакет
B2: ✓ — входит. Электричество: предложение — базовая мощность в цене, сверх — доплата (сейчас цена одна для любой мощности).
B4: Пакет | C4: Город | D4: Торговое место | E4: Вывеска с названием | F4: Печать меню | G4: Эквайринг Сбера (спецусловия) | H4: Клининг | I4: Вода | J4: Электро-подключение, кВт | K4: За доплату
B5: Корнер 3×3, основной фудкорт | C5: Мск / СПб | D5: 3×3 м | E5: ✓ | F5: ✓ | G5: ✓ | H5: ✓ | I5: ✓ | J5: до 5 кВт | K5: Доп. кВт, выбор места, продвижение в соцсетях, фото/видео, ночное хранение, Гастрогостиная, доп. персонал
B6: Корнер 6×3 (двойной) | C6: Мск / СПб | D6: 6×3 м | E6: ✓ (2 шт) | F6: ✓ | G6: ✓ | H6: ✓ | I6: ✓ | J6: до 10 кВт | K6: Доп. кВт, выбор места, продвижение в соцсетях, фото/видео, ночное хранение, Гастрогостиная, доп. персонал
B7: Корнер 4,5×3, деревянный фудкорт | C7: Мск / СПб | D7: 4,5×3 м | E7: ✓ | F7: ✓ | G7: ✓ | H7: ✓ | I7: ✓ | J7: до 5 кВт | K7: Доп. кВт, выбор места, продвижение в соцсетях, фото/видео, ночное хранение, Гастрогостиная, доп. персонал
B8: Шатёр-кухня 5×5, фудкорт Купер | C8: Мск | D8: 5×5 м | E8: ✓ | F8: ✓ | G8: ✓ | H8: ✓ | I8: ✓ | J8: до 15 кВт | K8: Доп. кВт, выбор места, продвижение в соцсетях, фото/видео, ночное хранение, Гастрогостиная, доп. персонал
B9: Корнер, фудкорт 2-й сцены | C9: Мск | D9: 3×3 м | E9: ✓ | F9: ✓ | G9: ✓ | H9: ✓ | I9: ✓ | J9: до 5 кВт | K9: Доп. кВт, выбор места, продвижение в соцсетях, фото/видео, ночное хранение, Гастрогостиная, доп. персонал
B10: VIP фудкорт (Smoke BBQ) | C10: Мск + СПб | D10: 4 + 3 точки | E10: ✓ | F10: ✓ | G10: ✓ | H10: ✓ | I10: ✓ | J10: по райдеру | K10: Доп. кВт, выбор места, продвижение в соцсетях, фото/видео, ночное хранение, Гастрогостиная, доп. персонал
B11: Тележка мороженого | C11: Мск / СПб | D11: тележка | E11: ✓ | F11: — | G11: ✓ | H11: ✓ | I11: — | J11: до 3 кВт | K11: Доп. кВт, выбор места, продвижение в соцсетях, фото/видео, ночное хранение, Гастрогостиная, доп. персонал
B12: Бар (партнёр) | C12: Мск + СПб | D12: по плану | E12: ✓ | F12: ✓ | G12: ✓ | H12: ✓ | I12: ✓ | J12: по райдеру | K12: Доп. кВт, выбор места, продвижение в соцсетях, фото/видео, ночное хранение, Гастрогостиная, доп. персонал
B14: Жёлтое (кВт) — предложение, утвердите с техпродакшном. Вывеска и вода для тележек — «—», уточнить.

Sheet Стратегия скидок
B1: Стратегия продаж и скидок 2027
B2: Принцип: не «даём скидку», а «цена растёт со временем». Скидка — только по правилам ниже, без торга.
B4: Волна | C4: Сроки | D4: Что продаём | E4: Цена | F4: Условия оплаты | G4: Лимит
B5: 0. Рассылка | C5: 22–26 декабря | D5: Презентация + оферта + прайс + опции всем резидентам 2026 и лонг-листу | E5: — | F5: — | G5: —
B6: 1. Ранний вход | C6: до 31 января | D6: Комбо Мск + СПб, VIP (Smoke BBQ), бар | E6: Комбо −10% к сумме двух мест | F6: 100% предоплата, без возврата (перенос на 2028 — по решению) | G6: Комбо ≤ 8 шт. железо+железо и ≤ 6 дерево+железо; после лимита — волна 2
B7: 2. Основная | C7: 1 февраля – 31 марта | D7: Одиночные места, комбо | E7: Комбо −5%; одиночные — по прайсу | F7: 50% при брони, 50% до 1 мая | G7: Комбо ≤ 30% мест основного фудкорта
B8: 3. Добор | C8: 1 апреля – 15 мая | D8: Оставшиеся места, опенколл | E8: По прайсу | F8: 100% при брони | G8: —
B9: 4. Последние места | C9: после 15 мая | D9: Свободные места | E9: Прайс +10% | F9: 100% сразу | G9: Только при наличии мест
B11: Правила скидок
B12: Кто даёт скидку | C12: Только руководитель гастронаправления. Менеджеры продают по прайсу и волнам.
B13: Максимум | C13: 10% к прайсу и никогда ниже с/с с НДС (столбец «Мин. цена» на листе «План продаж»).
B14: За что скидка | C14: Только за деньги раньше (волна 1) или объём (комбо, 2+ точки). Не за «просьбу» и не за «давно работаем».
B15: Вместо скидки | C15: Бонус-опция с низкой себестоимостью: выбор места, продвижение в соцсетях, Гастрогостиная, доп. аккредитации.
B16: Якорные резиденты (уровень A) | C16: Не скидка, а модель 60/40 или фикс + %: платят меньше заранее, больше — если хорошо торгуют.
B17: Не суммируются | C17: Ранняя скидка и комбо — одна скидка: комбо в январе = −10% всего, не 10% + 5%.
B18: Фиксация | C18: Каждая скидка — в CRM/реестре: кто, сколько, почему. Раз в месяц — сумма скидок против плана.
